Workbook

Sheet Instructions
B2: i-Finance UAT Script
B3: Freelancers (App 203) — Registrations, Contracts, Payments
B5: Environment URL | C5: (fill in: e.g. http://localhost:8080 or the deployed URL)
B6: Build / version date | C6: 2026-06-12 (Phase 4)
B7: UAT round
B8: Lead tester
B9: Start date
B10: End date
B12: How to test
B13: 1. Each tab is one functional area. Work top-to-bottom; one row = one test case.
B14: 2. Follow the Steps column exactly; compare the outcome with Expected Result.
B15: 2b. Sample Data / Records tells you WHICH seeded record, account or value to use — prefer it over inventing your own so results are reproducible.
B16: 3. Set Status from the dropdown: Pass / Fail / Blocked / N/A.
B17: 4. On Fail or Blocked, ALWAYS fill Comments (what happened, screenshots reference, error text).
B18: 5. Fill Tested By + Test Date on every executed row.
B19: 6. Login accounts: use the quick-login buttons on the login page, or accounts provided by the admin. Never write passwords in this file.
... B22: Status legend
B23: Pass | C23: Works exactly as the Expected Result describes
B24: Fail | C24: Does not match the Expected Result (describe in Comments)
B25: Blocked | C25: Cannot be executed (missing data/role/dependency failed)
B26: N/A | C26: Not applicable to this round/role
B28: Seeded UAT data (your starting point)
B29: - FL roles: AYESHA.AMERI = FL_ADMIN, NASER.ALKHAJA = FL_MANAGER, SHAIKHA.GALAMERI = FL_USER.
B30: - Layla Hassan (FL-VND-000001) - ACTIVE freelancer with bank account, documents and contract FL-CON-000001 (24k, ACTIVE, 1 voucher PAID): use for detail/schedule/voucher tests.
B31: - FL-CON-000002 (84k) - pending at the FL_ADMIN step: use for the >=50k two-step approval test.
B32: - FL-REG-000004 (Omar Saleh) - DRAFT; FL-REG-000005 (Mariam Khalil) - SUBMITTED, in the manager queue.
B33: - One amendment, one deliverable, one renewal and near-expiry documents exist from the lifecycle seed.
B35: Live summary
B36: Functional area | C36: Cases | D36: Pass | E36: Fail | F36: Blocked | G36: Executed %
B37: Access & Session | C37: 3 | D37: =COUNTIF('Access & Session'!G:G,"Pass") | E37: =COUNTIF('Access & Session'!G:G,"Fail") | F37: =COUNTIF('Access & Session'!G:G,"Blocked") | G37: =ROUND(COUNTA('Access & Session'!G2:G500)/C37*100,0)&"%"
B38: Dashboard | C38: 2 | D38: =COUNTIF('Dashboard'!G:G,"Pass") | E38: =COUNTIF('Dashboard'!G:G,"Fail") | F38: =COUNTIF('Dashboard'!G:G,"Blocked") | G38: =ROUND(COUNTA('Dashboard'!G2:G500)/C38*100,0)&"%"
B39: Registrations | C39: 5 | D39: =COUNTIF('Registrations'!G:G,"Pass") | E39: =COUNTIF('Registrations'!G:G,"Fail") | F39: =COUNTIF('Registrations'!G:G,"Blocked") | G39: =ROUND(COUNTA('Registrations'!G2:G500)/C39*100,0)&"%"
B40: Freelancers | C40: 5 | D40: =COUNTIF('Freelancers'!G:G,"Pass") | E40: =COUNTIF('Freelancers'!G:G,"Fail") | F40: =COUNTIF('Freelancers'!G:G,"Blocked") | G40: =ROUND(COUNTA('Freelancers'!G2:G500)/C40*100,0)&"%"
B41: Contracts | C41: 7 | D41: =COUNTIF('Contracts'!G:G,"Pass") | E41: =COUNTIF('Contracts'!G:G,"Fail") | F41: =COUNTIF('Contracts'!G:G,"Blocked") | G41: =ROUND(COUNTA('Contracts'!G2:G500)/C41*100,0)&"%"
B42: Payments | C42: 5 | D42: =COUNTIF('Payments'!G:G,"Pass") | E42: =COUNTIF('Payments'!G:G,"Fail") | F42: =COUNTIF('Payments'!G:G,"Blocked") | G42: =ROUND(COUNTA('Payments'!G2:G500)/C42*100,0)&"%"
B43: Compliance | C43: 2 | D43: =COUNTIF('Compliance'!G:G,"Pass") | E43: =COUNTIF('Compliance'!G:G,"Fail") | F43: =COUNTIF('Compliance'!G:G,"Blocked") | G43: =ROUND(COUNTA('Compliance'!G2:G500)/C43*100,0)&"%"
B44: Approvals | C44: 3 | D44: =COUNTIF('Approvals'!G:G,"Pass") | E44: =COUNTIF('Approvals'!G:G,"Fail") | F44: =COUNTIF('Approvals'!G:G,"Blocked") | G44: =ROUND(COUNTA('Approvals'!G2:G500)/C44*100,0)&"%"
B45: Administration | C45: 1 | D45: =COUNTIF('Administration'!G:G,"Pass") | E45: =COUNTIF('Administration'!G:G,"Fail") | F45: =COUNTIF('Administration'!G:G,"Blocked") | G45: =ROUND(COUNTA('Administration'!G2:G500)/C45*100,0)&"%"
B46: Shell & Language | C46: 2 | D46: =COUNTIF('Shell & Language'!G:G,"Pass") | E46: =COUNTIF('Shell & Language'!G:G,"Fail") | F46: =COUNTIF('Shell & Language'!G:G,"Blocked") | G46: =ROUND(COUNTA('Shell & Language'!G2:G500)/C46*100,0)&"%"
B47: Enhancements | C47: 5 | D47: =COUNTIF('Enhancements'!G:G,"Pass") | E47: =COUNTIF('Enhancements'!G:G,"Fail") | F47: =COUNTIF('Enhancements'!G:G,"Blocked") | G47: =ROUND(COUNTA('Enhancements'!G2:G500)/C47*100,0)&"%"
...

Sheet Access & Session
A1: Test ID | B1: Function | C1: Test Scenario | D1: Steps | E1: Sample Data / Records | F1: Expected Result | G1: Status | H1: Tested By | I1: Test Date | J1: Comments / Defect Ref
A2: FL-ACC-01 | B2: Shared session | C2: Entry from Admin | D2: 1. Login in Admin 2. Switch to Freelancers via the module dropdown | E2: FL_USER = SHAIKHA.GALAMERI · FL_MANAGER = NASER.ALKHAJA · FL_ADMIN = AYESHA.AMERI | F2: FL opens logged-in; viewer/manager/admin nav per role (FL_USER / FL_MANAGER / FL_ADMIN)
A3: FL-ACC-02 | B3: No session | C3: Direct open without login | D3: 1. Fresh private window > FL URL | E3: FL_USER = SHAIKHA.GALAMERI · FL_MANAGER = NASER.ALKHAJA · FL_ADMIN = AYESHA.AMERI | F3: Redirected to Admin login
A4: FL-ACC-03 | B4: Role gating | C4: Compliance/Approvals/Admin menus | D4: 1. Compare menus as FL_USER (SHAIKHA.GALAMERI) vs FL_MANAGER (NASER) vs FL_ADMIN (AYESHA) | E4: FL_USER = SHAIKHA.GALAMERI · FL_MANAGER = NASER.ALKHAJA · FL_ADMIN = AYESHA.AMERI | F4: Compliance + Approvals groups appear for managers+; Module Settings only for FL_ADMIN/SYS_ADMIN

Sheet Dashboard
A1: Test ID | B1: Function | C1: Test Scenario | D1: Steps | E1: Sample Data / Records | F1: Expected Result | G1: Status | H1: Tested By | I1: Test Date | J1: Comments / Defect Ref
A2: FL-DSH-01 | B2: Stats | C2: Cards show live numbers | D2: 1. Open FL Dashboard | F2: Active freelancers, active contracts (+AED total), vouchers awaiting approval, documents expiring — all sensible values
A3: FL-DSH-02 | B3: Charts | C3: Spend + expiry horizon | D3: 1. Wait for both charts | F3: Committed-vs-Paid by organisation bar chart + document expiry horizon chart render with data

Sheet Registrations
A1: Test ID | B1: Function | C1: Test Scenario | D1: Steps | E1: Sample Data / Records | F1: Expected Result | G1: Status | H1: Tested By | I1: Test Date | J1: Comments / Defect Ref
A2: FL-REG-01 | B2: List | C2: Paged list + search | D2: 1. Open Registrations 2. Search by name 3. Filter by status | E2: FL-REG-000004 (Omar Saleh, DRAFT) · FL-REG-000005 (Mariam Khalil, SUBMITTED) | F2: Server-paged list; filters work; FL-REG numbers shown
A3: FL-REG-02 | B3: Create | C3: New registration draft | D3: 1. + New Registration: names, date of birth, nationality, email, mobile, specialization 2. Save | E3: Name 'Test Freelancer UAT' · nationality from dropdown · test.fl.uat@example.com | F3: Draft saved with FL-REG-NNNNNN number; appears in the list as DRAFT
A4: FL-REG-03 | B4: Photo | C4: Photo required to submit | D4: 1. Open a DRAFT registration without a photo 2. Try Submit 3. Upload a photo and submit again | E4: FL-REG-000004 (no photo yet) · any JPG/PNG | F4: Submit blocked until a photo is uploaded; with photo it submits
A5: FL-REG-04 | B5: Submit | C5: Send for approval | D5: 1. Submit a complete draft | E5: Your draft from the previous case (photo uploaded) | F5: Status SUBMITTED; appears in the FL manager's approvals queue
A6: FL-REG-05 | B6: Approve | C6: Approval creates the freelancer | D6: 1. As FL_MANAGER approve the registration (then FL_ADMIN if a second step shows) | E6: FL-REG-000005 — in NASER.ALKHAJA's queue | F6: On final approval a freelancer profile is created automatically with a FL-VND vendor number

Sheet Freelancers
A1: Test ID | B1: Function | C1: Test Scenario | D1: Steps | E1: Sample Data / Records | F1: Expected Result | G1: Status | H1: Tested By | I1: Test Date | J1: Comments / Defect Ref
A2: FL-VND-01 | B2: List | C2: Directory | D2: 1. Open Freelancers | E2: Layla Hassan — FL-VND-000001 (ACTIVE) | F2: Active freelancers with vendor number, name, specialization, status
A3: FL-VND-02 | B3: Detail | C3: Tabs | D3: 1. Open a freelancer | E3: FL-VND-000001 (has bank account, contract, documents) | F3: Profile / Bank Accounts / Contracts / Documents tabs all load; audit info shows created/updated in local time
A4: FL-VND-03 | B4: Bank | C4: Add bank account | D4: 1. In Bank Accounts add IBAN/bank details 2. Save | E4: IBAN AE07 0331 2345 6789 0123 456 · any seeded bank | F4: Account listed; primary flag honoured
A5: FL-VND-04 | B5: Status | C5: Change status | D5: 1. Use Change Status (e.g. ACTIVE > INACTIVE and back) | F5: Status updates with a reason; reflected in the list
A6: FL-VND-05 | B6: Documents | C6: Add document with expiry | D6: 1. In Documents add a document with a near-future expiry 2. Upload the file | E6: Expiry +20 days (so it appears in Compliance) | F6: Document saved; appears in Compliance > Documents with days-to-expiry

Sheet Contracts
A1: Test ID | B1: Function | C1: Test Scenario | D1: Steps | E1: Sample Data / Records | F1: Expected Result | G1: Status | H1: Tested By | I1: Test Date | J1: Comments / Defect Ref
A2: FL-CON-01 | B2: List | C2: Contracts with billing bar | D2: 1. Open Contracts | E2: FL-CON-000001 (24k ACTIVE, ~17% billed) · FL-CON-000002 (84k, pending) | F2: Contracts with totals, status and % billed progress bar
A3: FL-CON-02 | B3: Create | C3: New contract draft | D3: 1. + New Contract: freelancer, title, dates, total amount, billing method, GL or Project coding 2. Save | E3: FL-VND-000001 · 12 months · GL coding from dropdown | F3: Draft saved with FL-CON number; GL/PROJECT coding toggle works
A4: FL-CON-03 | B4: Submit small | C4: < 50k = 1 approval step | D4: 1. Submit a contract under AED 50,000 2. Approve as FL_MANAGER | E4: Amount 24,000 — approve as NASER.ALKHAJA only | F4: Contract becomes ACTIVE after ONE approval; payment schedule generated automatically
A5: FL-CON-04 | B5: Submit large | C5: >= 50k = 2 approval steps | D5: 1. Submit a contract of AED 50,000+ (seeded: FL-CON-000002, 84k) 2. Approve as FL_MANAGER | E5: FL-CON-000002 (84k) — already at step 2; approve as AYESHA.AMERI (FL_ADMIN) | F5: After step 1 it is still pending at the FL_ADMIN step; only after step 2 does it activate
A6: FL-CON-05 | B6: Detail | C6: Schedule + tabs | D6: 1. Open an ACTIVE contract | E6: FL-CON-000001 — 6 monthly rows, June PAID | F6: Payment Schedule / Amendments / Renewals / Details tabs; schedule rows match the billing method
A7: FL-CON-06 | B7: Amendment | C7: Amend amount/end date | D7: 1. + Amendment on an ACTIVE contract 2. Submit and approve it | E7: FL-CON-000001 — one amendment already exists as reference | F7: On approval the contract values update, version +1, schedule rebuilt
A8: FL-CON-07 | B8: Renewal | C8: Renew a contract | D8: 1. Renew from the contract detail 2. Submit and approve | F8: A new contract version/row is created per the renewal terms

Sheet Payments
A1: Test ID | B1: Function | C1: Test Scenario | D1: Steps | E1: Sample Data / Records | F1: Expected Result | G1: Status | H1: Tested By | I1: Test Date | J1: Comments / Defect Ref
A2: FL-PAY-01 | B2: Schedule | C2: Due worklist | D2: 1. Open Payment Schedule | E2: FL-CON-000001 schedule — July onwards PENDING | F2: Due/pending schedule rows across contracts with Generate Voucher actions
A3: FL-PAY-02 | B3: Voucher | C3: Generate from schedule | D3: 1. Click Generate Voucher on a due row | E3: July 2026 row of FL-CON-000001 | F3: Voucher FL-VCH created in DRAFT linked to the schedule row
A4: FL-PAY-03 | B4: Voucher | C4: Invoice + submit | D4: 1. Open the voucher detail 2. Enter invoice reference 3. Submit and approve | E4: Invoice ref INV-UAT-001 | F4: Voucher APPROVED; schedule row marked voucher-generated
A5: FL-PAY-04 | B5: Mark paid | C5: FL_ADMIN settles | D5: 1. As FL_ADMIN use Mark Paid on an approved voucher | E5: Login AYESHA.AMERI — FL-VCH-000001 is the PAID reference | F5: Payment status PAID; contract paid-total and % billed update
A6: FL-PAY-05 | B6: Deliverables | C6: Accept / reject | D6: 1. Open Deliverables 2. Accept one and reject another with a reason | F6: States update; reason stored

Sheet Compliance
A1: Test ID | B1: Function | C1: Test Scenario | D1: Steps | E1: Sample Data / Records | F1: Expected Result | G1: Status | H1: Tested By | I1: Test Date | J1: Comments / Defect Ref
A2: FL-CMP-01 | B2: Documents | C2: Expiry filter + badge | D2: 1. Open Compliance > Documents 2. Use the expiry filter (Expired / Expiring Soon / Valid) | E2: Seeded near-expiry document on FL-VND-000001 | F2: Filtered list with days-to-expiry; side-nav badge matches the expiring count
A3: FL-CMP-02 | B3: Navigate | C3: Document to freelancer | D3: 1. Click a document row | F3: Opens the owning freelancer's Documents tab

Sheet Approvals
A1: Test ID | B1: Function | C1: Test Scenario | D1: Steps | E1: Sample Data / Records | F1: Expected Result | G1: Status | H1: Tested By | I1: Test Date | J1: Comments / Defect Ref
A2: FL-APR-01 | B2: Queue | C2: Pending list | D2: 1. Login as FL_MANAGER (NASER) 2. Open Pending Approvals | E2: Login NASER.ALKHAJA; pending: FL-REG-000005 (registration) + FL-CON-000002 (84k contract, step 2) | F2: FL registrations/contracts/vouchers awaiting YOUR step; badge count matches
A3: FL-APR-02 | B3: Comment required | C3: Approve needs a comment | D3: 1. Click Approve and try to confirm with an empty comment | E3: Login NASER.ALKHAJA; pending: FL-REG-000005 (registration) + FL-CON-000002 (84k contract, step 2) | F3: Blocked with 'a comment is required'; with a comment it succeeds
A4: FL-APR-03 | B4: Reject / Return | C4: Negative paths | D4: 1. Reject one item; Return another (with comments) | E4: Login NASER.ALKHAJA; pending: FL-REG-000005 (registration) + FL-CON-000002 (84k contract, step 2) | F4: Statuses update; requester notified; returned item editable again

Sheet Administration
A1: Test ID | B1: Function | C1: Test Scenario | D1: Steps | E1: Sample Data / Records | F1: Expected Result | G1: Status | H1: Tested By | I1: Test Date | J1: Comments / Defect Ref
A2: FL-ADM-01 | B2: Module settings | C2: FL settings | D2: 1. As FL_ADMIN open Module Settings 2. Edit a value (e.g. DOC_EXPIRY_ALERT_DAYS) 3. Save + refresh | E2: DOC_EXPIRY_ALERT_DAYS (restore the value after) | F2: Persists; non-admins do not see the page

Sheet Shell & Language
A1: Test ID | B1: Function | C1: Test Scenario | D1: Steps | E1: Sample Data / Records | F1: Expected Result | G1: Status | H1: Tested By | I1: Test Date | J1: Comments / Defect Ref
A2: FL-SHL-01 | B2: Switcher | C2: Cross-module hop | D2: 1. Module dropdown > Admin / CC and back | F2: No re-login; FL shows live (no 'soon' badge)
A3: FL-SHL-02 | B3: Arabic | C3: RTL pass | D3: 1. Switch to AR 2. Walk Dashboard + Registrations + a contract detail | F3: Mirrored layout, Arabic labels, Latin digits; charts re-render

Sheet Enhancements
A1: Test ID | B1: Function | C1: Test Scenario | D1: Steps | E1: Sample Data / Records | F1: Expected Result | G1: Status | H1: Tested By | I1: Test Date | J1: Comments / Defect Ref
A2: FL-ENH-01 | B2: Compliance deep link | C2: Doc row opens Documents tab | D2: 1. Open Compliance > Documents 2. Click a document row | F2: Freelancer detail opens directly on the Documents tab (not Profile) — FL-CMP-02 fix
A3: FL-ENH-02 | B3: Bulk kill switch | C3: Bulk button respects setting | D3: 1. With ALLOW_BULK_VOUCHER_GENERATION = N open Payment Schedule 2. Call POST /fl/schedule/bulk-generate directly | F3: No 'Generate All Due' button on the page; direct API call refused with 403
A4: FL-ENH-03 | B4: Bulk generation | C4: Generate all due vouchers | D4: 1. Set ALLOW_BULK_VOUCHER_GENERATION = Y 2. Reload Payment Schedule 3. Generate All Due > Generate 4. Restore the setting to N | F4: Button appears; one DRAFT voucher per PENDING row without an open voucher; rows flip to VOUCHER_GENERATED; toast shows the created count
A5: FL-ENH-04 | B5: Unsaved changes guard | C5: Dirty form warns on navigation | D5: 1. Open a contract/registration edit form 2. Change a field without saving 3. Click another nav item | F5: Confirm dialog about unsaved changes; Cancel stays, OK leaves; after Save no warning
A6: FL-ENH-05 | B6: Command palette | C6: Ctrl+K navigation | D6: 1. Press Ctrl+K anywhere in FL 2. Type a page name and press Enter | F6: Palette opens with FL navigation entries; Enter navigates to the page
