Workbook

Sheet Projects Cashflow
K1: =SUBTOTAL(9,K3:K1048576) -> 1574767 | L1: =SUBTOTAL(9,L3:L1048576) -> 10563367 | M1: =SUBTOTAL(9,M3:M1048576) -> 1.2557259e+09 | N1: =SUBTOTAL(9,N3:N1048576) -> 5.3993238e+08 | O1: =SUBTOTAL(9,O3:O1048576) -> 4.3767954e+08 | P1: =SUBTOTAL(9,P3:P1048576) -> 4.9824083e+08 | Q1: =SUBTOTAL(9,Q3:Q1048576) -> 2.4776673e+08 | R1: =SUBTOTAL(9,R3:R1048576) -> 3.2591407e+08 | ... W1: =SUBTOTAL(9,W3:W1048576) -> 5.08522e+09 | AG1: =SUBTOTAL(9,AG3:AG1048576) -> 7.694308e+09 | AH1: =SUBTOTAL(9,AH3:AH1048576) -> 5.3650702e+09
B2: Com | C2: COST_CENTER | D2: PROJECT2 | E2: PROJECT_NAME | F2: TASK | G2: GL | H2: Future | I2: EXPENDITURE_TYPE | J2: CF_TYPE | K2: 01-2026 | L2: 02-2026 | M2: 03-2026 | N2: 04-2026 | O2: 05-2026 | P2: 06-2026 | Q2: 07-2026 | R2: 08-2026 | S2: 09-2026 | T2: 10-2026 | U2: 11-2026 | V2: 12-2026 | W2: Total | X2: GL_COMBINATION | Y2: SECTOR | Z2: DEPARTMENT | AA2: GL_ACCOUNT | AB2: APPROPRIATION | AC2: CHAPTER | AD2: PROGRAM | AE2: BUSINESS_UNIT | AF2: PROJECT_TYPE | AG2: ANNUAL_BUDGET | AH2: Total V3
B3: =C3&D3&F3&G3&H3 -> 45100114511000015Sponsorship Fees-N1424811200104 | C3: 4510011 | D3: 4511000015 | E3: Ex-SH-MNS | F3: Sponsorship Fees-N1 | G3: 424811 | H3: 200104 | I3: 424811 - Sponsorship expenses/contributions | J3: APPROVED | K3: =_xlfn.XLOOKUP(B3,[1]Sheet1!$B:$B,[1]Sheet1!$N:$N,0) -> 0 | L3: =_xlfn.XLOOKUP(B3,[1]Sheet1!$B:$B,[1]Sheet1!$O:$O,0) -> 0 | M3: =_xlfn.XLOOKUP(B3,[1]Sheet1!$B:$B,[1]Sheet1!$P:$P,0) -> 30000000 | N3: =_xlfn.XLOOKUP(B3,[1]Sheet1!$B:$B,[1]Sheet1!$Q:$Q,0) -> 0 | O3: =_xlfn.XLOOKUP(B3,[1]Sheet1!$B:$B,[1]Sheet1!$R:$R,0) -> 0 | P3: =_xlfn.XLOOKUP(B3,[1]Sheet1!$B:$B,[1]Sheet1!$S:$S,0) -> 0 | Q3: =_xlfn.XLOOKUP(B3,[1]Sheet1!$B:$B,[1]Sheet1!$T:$T,0) -> 0 | R3: =_xlfn.XLOOKUP(B3,[1]Sheet1!$B:$B,[1]Sheet1!$U:$U,0) -> 0 | S3: =_xlfn.XLOOKUP(B3,[1]Sheet1!$B:$B,[1]Sheet1!$V:$V,0) -> 0 | T3: =_xlfn.XLOOKUP(B3,[1]Sheet1!$B:$B,[1]Sheet1!$W:$W,0) -> 0 | U3: =_xlfn.XLOOKUP(B3,[1]Sheet1!$B:$B,[1]Sheet1!$X:$X,0) -> 0 | V3: =_xlfn.XLOOKUP(B3,[1]Sheet1!$B:$B,[1]Sheet1!$Y:$Y,0) -> 0 | W3: =SUM(K3:V3) -> 30000000 | X3: 451.070101.4510011.1.424811.4510000.200104.000.000000.000000 | Y3: Executive Office | Z3: DCT - Executive Affairs Department | AA3: 424811 - Sponsorship expenses/contributions | AB3: 200104 - FA104-Opex Expense | AC3: Chapter 2 | AD3: 070101 - Corporate Office | AE3: Department of Culture and Tourism | AF3: DCT OPEX Project Type | AG3: 30000000 | AH3: =_xlfn.XLOOKUP(B3,[1]Sheet1!$B:$B,[1]Sheet1!$AB:$AB,0) -> 30000000
B4: =C4&D4&F4&G4&H4 -> 45101404511000016Audit Services-N421125200104 | C4: 4510140 | D4: 4511000016 | E4: EX-INR Audit | F4: Audit Services-N | G4: 421125 | H4: 200104 | I4: 421125 - Professional Operational Service expenses | J4: APPROVED | K4: =_xlfn.XLOOKUP(B4,[1]Sheet1!$B:$B,[1]Sheet1!$N:$N,0) -> 0 | L4: =_xlfn.XLOOKUP(B4,[1]Sheet1!$B:$B,[1]Sheet1!$O:$O,0) -> 0 | M4: =_xlfn.XLOOKUP(B4,[1]Sheet1!$B:$B,[1]Sheet1!$P:$P,0) -> 0 | N4: =_xlfn.XLOOKUP(B4,[1]Sheet1!$B:$B,[1]Sheet1!$Q:$Q,0) -> 454200 | O4: =_xlfn.XLOOKUP(B4,[1]Sheet1!$B:$B,[1]Sheet1!$R:$R,0) -> 142800 | P4: =_xlfn.XLOOKUP(B4,[1]Sheet1!$B:$B,[1]Sheet1!$S:$S,0) -> 142800 | Q4: =_xlfn.XLOOKUP(B4,[1]Sheet1!$B:$B,[1]Sheet1!$T:$T,0) -> 142800 | R4: =_xlfn.XLOOKUP(B4,[1]Sheet1!$B:$B,[1]Sheet1!$U:$U,0) -> 142800 | S4: =_xlfn.XLOOKUP(B4,[1]Sheet1!$B:$B,[1]Sheet1!$V:$V,0) -> 464500 | T4: =_xlfn.XLOOKUP(B4,[1]Sheet1!$B:$B,[1]Sheet1!$W:$W,0) -> 342800 | U4: =_xlfn.XLOOKUP(B4,[1]Sheet1!$B:$B,[1]Sheet1!$X:$X,0) -> 802800 | V4: =_xlfn.XLOOKUP(B4,[1]Sheet1!$B:$B,[1]Sheet1!$Y:$Y,0) -> 464500 | W4: =SUM(K4:V4) -> 3100000 | X4: 451.070109.4510140.1.421125.4510000.200104.000.000000.000000 | Y4: Internal Audit | Z4: DCT - Internal Audit Dept | AA4: 421125 - Professional Operational Service expenses | AB4: 200104 - FA104-Opex Expense | AC4: Chapter 2 | AD4: 070109 - Internal Audit and Risk Management | AE4: Department of Culture and Tourism | AF4: DCT OPEX Project Type | AG4: 2669667 | AH4: =_xlfn.XLOOKUP(B4,[1]Sheet1!$B:$B,[1]Sheet1!$AB:$AB,0) -> 2669667
B5: =C5&D5&F5&G5&H5 -> 45101404511000016Freelancers-N424521200104 | C5: 4510140 | D5: 4511000016 | E5: EX-INR Audit | F5: Freelancers-N | G5: 424521 | H5: 200104 | I5: 424521 - Manpower supply "Other Than IT Related" | J5: APPROVED | K5: =_xlfn.XLOOKUP(B5,[1]Sheet1!$B:$B,[1]Sheet1!$N:$N,0) -> 0 | L5: =_xlfn.XLOOKUP(B5,[1]Sheet1!$B:$B,[1]Sheet1!$O:$O,0) -> 0 | M5: =_xlfn.XLOOKUP(B5,[1]Sheet1!$B:$B,[1]Sheet1!$P:$P,0) -> 0 | N5: =_xlfn.XLOOKUP(B5,[1]Sheet1!$B:$B,[1]Sheet1!$Q:$Q,0) -> 0 | O5: =_xlfn.XLOOKUP(B5,[1]Sheet1!$B:$B,[1]Sheet1!$R:$R,0) -> 0 | P5: =_xlfn.XLOOKUP(B5,[1]Sheet1!$B:$B,[1]Sheet1!$S:$S,0) -> 0 | Q5: =_xlfn.XLOOKUP(B5,[1]Sheet1!$B:$B,[1]Sheet1!$T:$T,0) -> 0 | R5: =_xlfn.XLOOKUP(B5,[1]Sheet1!$B:$B,[1]Sheet1!$U:$U,0) -> 0 | S5: =_xlfn.XLOOKUP(B5,[1]Sheet1!$B:$B,[1]Sheet1!$V:$V,0) -> 0 | T5: =_xlfn.XLOOKUP(B5,[1]Sheet1!$B:$B,[1]Sheet1!$W:$W,0) -> 0 | U5: =_xlfn.XLOOKUP(B5,[1]Sheet1!$B:$B,[1]Sheet1!$X:$X,0) -> 0 | V5: =_xlfn.XLOOKUP(B5,[1]Sheet1!$B:$B,[1]Sheet1!$Y:$Y,0) -> 0 | W5: =SUM(K5:V5) -> 0 | X5: 451.070109.4510140.1.424521.4510000.200104.000.000000.000000 | Y5: Internal Audit | Z5: DCT - Internal Audit Dept | AA5: 424521 - Manpower supply Other Than IT Related | AB5: 200104 - FA104-Opex Expense | AC5: Chapter 2 | AD5: 070109 - Internal Audit and Risk Management | AE5: Department of Culture and Tourism | AF5: DCT OPEX Project Type | AG5: 430333 | AH5: =_xlfn.XLOOKUP(B5,[1]Sheet1!$B:$B,[1]Sheet1!$AB:$AB,0) -> 430333
B6: =C6&D6&F6&G6&H6 -> 45101404511000016Mission & Travel-N423821200104 | C6: 4510140 | D6: 4511000016 | E6: EX-INR Audit | F6: Mission & Travel-N | G6: 423821 | H6: 200104 | I6: 423821 - Business Travel - Per Diem Allowances | J6: APPROVED | K6: =_xlfn.XLOOKUP(B6,[1]Sheet1!$B:$B,[1]Sheet1!$N:$N,0) -> 0 | L6: =_xlfn.XLOOKUP(B6,[1]Sheet1!$B:$B,[1]Sheet1!$O:$O,0) -> 0 | M6: =_xlfn.XLOOKUP(B6,[1]Sheet1!$B:$B,[1]Sheet1!$P:$P,0) -> 0 | N6: =_xlfn.XLOOKUP(B6,[1]Sheet1!$B:$B,[1]Sheet1!$Q:$Q,0) -> 0 | O6: =_xlfn.XLOOKUP(B6,[1]Sheet1!$B:$B,[1]Sheet1!$R:$R,0) -> 0 | P6: =_xlfn.XLOOKUP(B6,[1]Sheet1!$B:$B,[1]Sheet1!$S:$S,0) -> 0 | Q6: =_xlfn.XLOOKUP(B6,[1]Sheet1!$B:$B,[1]Sheet1!$T:$T,0) -> 0 | R6: =_xlfn.XLOOKUP(B6,[1]Sheet1!$B:$B,[1]Sheet1!$U:$U,0) -> 0 | S6: =_xlfn.XLOOKUP(B6,[1]Sheet1!$B:$B,[1]Sheet1!$V:$V,0) -> 0 | T6: =_xlfn.XLOOKUP(B6,[1]Sheet1!$B:$B,[1]Sheet1!$W:$W,0) -> 0 | U6: =_xlfn.XLOOKUP(B6,[1]Sheet1!$B:$B,[1]Sheet1!$X:$X,0) -> 125000 | V6: =_xlfn.XLOOKUP(B6,[1]Sheet1!$B:$B,[1]Sheet1!$Y:$Y,0) -> 0 | W6: =SUM(K6:V6) -> 125000 | X6: 451.070109.4510140.1.423821.4510000.200104.000.000000.000000 | Y6: Internal Audit | Z6: DCT - Internal Audit Dept | AA6: 423821 - Business Travel - Per Diem Allowances | AB6: 200104 - FA104-Opex Expense | AC6: Chapter 2 | AD6: 070109 - Internal Audit and Risk Management | AE6: Department of Culture and Tourism | AF6: DCT OPEX Project Type | AG6: 125000 | AH6: =_xlfn.XLOOKUP(B6,[1]Sheet1!$B:$B,[1]Sheet1!$AB:$AB,0) -> 125000
B7: =C7&D7&F7&G7&H7 -> 45101404511000016Other Expenses-N424991200104 | C7: 4510140 | D7: 4511000016 | E7: EX-INR Audit | F7: Other Expenses-N | G7: 424991 | H7: 200104 | I7: 424991 - Other services, not specifically mentioned elsewhere | J7: APPROVED | K7: =_xlfn.XLOOKUP(B7,[1]Sheet1!$B:$B,[1]Sheet1!$N:$N,0) -> 0 | L7: =_xlfn.XLOOKUP(B7,[1]Sheet1!$B:$B,[1]Sheet1!$O:$O,0) -> 0 | M7: =_xlfn.XLOOKUP(B7,[1]Sheet1!$B:$B,[1]Sheet1!$P:$P,0) -> 2926.04 | N7: =_xlfn.XLOOKUP(B7,[1]Sheet1!$B:$B,[1]Sheet1!$Q:$Q,0) -> 0 | O7: =_xlfn.XLOOKUP(B7,[1]Sheet1!$B:$B,[1]Sheet1!$R:$R,0) -> 0 | P7: =_xlfn.XLOOKUP(B7,[1]Sheet1!$B:$B,[1]Sheet1!$S:$S,0) -> 0 | Q7: =_xlfn.XLOOKUP(B7,[1]Sheet1!$B:$B,[1]Sheet1!$T:$T,0) -> 0 | R7: =_xlfn.XLOOKUP(B7,[1]Sheet1!$B:$B,[1]Sheet1!$U:$U,0) -> 0 | S7: =_xlfn.XLOOKUP(B7,[1]Sheet1!$B:$B,[1]Sheet1!$V:$V,0) -> 59574 | T7: =_xlfn.XLOOKUP(B7,[1]Sheet1!$B:$B,[1]Sheet1!$W:$W,0) -> 0 | U7: =_xlfn.XLOOKUP(B7,[1]Sheet1!$B:$B,[1]Sheet1!$X:$X,0) -> 62500 | V7: =_xlfn.XLOOKUP(B7,[1]Sheet1!$B:$B,[1]Sheet1!$Y:$Y,0) -> 0 | W7: =SUM(K7:V7) -> 125000.04 | X7: 451.070109.4510140.1.424991.4510000.200104.000.000000.000000 | Y7: Internal Audit | Z7: DCT - Internal Audit Dept | AA7: 424991 - Other services, not specifically mentioned elsewhere | AB7: 200104 - FA104-Opex Expense | AC7: Chapter 2 | AD7: 070109 - Internal Audit and Risk Management | AE7: Department of Culture and Tourism | AF7: DCT OPEX Project Type | AG7: 125000 | AH7: =_xlfn.XLOOKUP(B7,[1]Sheet1!$B:$B,[1]Sheet1!$AB:$AB,0) -> 125000.04
B8: =C8&D8&F8&G8&H8 -> 45112504511000019Activation&Prog-N422401200104 | C8: 4511250 | D8: 4511000019 | E8: CS-Art Comm-Qatara | F8: Activation&Prog-N | G8: 422401 | H8: 200104 | I8: 422401 - Conferences, seminars, exhib ,events: -deactivate | J8: APPROVED | K8: =_xlfn.XLOOKUP(B8,[1]Sheet1!$B:$B,[1]Sheet1!$N:$N,0) -> 0 | L8: =_xlfn.XLOOKUP(B8,[1]Sheet1!$B:$B,[1]Sheet1!$O:$O,0) -> 0 | M8: =_xlfn.XLOOKUP(B8,[1]Sheet1!$B:$B,[1]Sheet1!$P:$P,0) -> 562600 | N8: =_xlfn.XLOOKUP(B8,[1]Sheet1!$B:$B,[1]Sheet1!$Q:$Q,0) -> 0 | O8: =_xlfn.XLOOKUP(B8,[1]Sheet1!$B:$B,[1]Sheet1!$R:$R,0) -> 0 | P8: =_xlfn.XLOOKUP(B8,[1]Sheet1!$B:$B,[1]Sheet1!$S:$S,0) -> 0 | Q8: =_xlfn.XLOOKUP(B8,[1]Sheet1!$B:$B,[1]Sheet1!$T:$T,0) -> 0 | R8: =_xlfn.XLOOKUP(B8,[1]Sheet1!$B:$B,[1]Sheet1!$U:$U,0) -> 0 | S8: =_xlfn.XLOOKUP(B8,[1]Sheet1!$B:$B,[1]Sheet1!$V:$V,0) -> 0 | T8: =_xlfn.XLOOKUP(B8,[1]Sheet1!$B:$B,[1]Sheet1!$W:$W,0) -> 0 | U8: =_xlfn.XLOOKUP(B8,[1]Sheet1!$B:$B,[1]Sheet1!$X:$X,0) -> 0 | V8: =_xlfn.XLOOKUP(B8,[1]Sheet1!$B:$B,[1]Sheet1!$Y:$Y,0) -> 430400 | W8: =SUM(K8:V8) -> 993000 | X8: 451.070205.4511250.1.422401.4510000.200104.000.000000.000000 | Y8: Culture | Z8: DCT - Culture Sites Management Department | AA8: 422401 - Conferences, seminars and exhibitions and other events: -deactivate | AB8: 200104 - FA104-Opex Expense | AC8: Chapter 2 | AD8: 070205 - Cultural site management | AE8: Department of Culture and Tourism | AF8: DCT OPEX Project Type | AG8: 993000 | AH8: =_xlfn.XLOOKUP(B8,[1]Sheet1!$B:$B,[1]Sheet1!$AB:$AB,0) -> 993000
B9: =C9&D9&F9&G9&H9 -> 45112504511000019Ad-hoc Repairs-N426427200104 | C9: 4511250 | D9: 4511000019 | E9: CS-Art Comm-Qatara | F9: Ad-hoc Repairs-N | G9: 426427 | H9: 200104 | I9: 426427 - Maintenance & repair-Exhibition Stands, etc | J9: APPROVED | K9: =_xlfn.XLOOKUP(B9,[1]Sheet1!$B:$B,[1]Sheet1!$N:$N,0) -> 0 | L9: =_xlfn.XLOOKUP(B9,[1]Sheet1!$B:$B,[1]Sheet1!$O:$O,0) -> 0 | M9: =_xlfn.XLOOKUP(B9,[1]Sheet1!$B:$B,[1]Sheet1!$P:$P,0) -> 0 | N9: =_xlfn.XLOOKUP(B9,[1]Sheet1!$B:$B,[1]Sheet1!$Q:$Q,0) -> 30000 | O9: =_xlfn.XLOOKUP(B9,[1]Sheet1!$B:$B,[1]Sheet1!$R:$R,0) -> 30000 | P9: =_xlfn.XLOOKUP(B9,[1]Sheet1!$B:$B,[1]Sheet1!$S:$S,0) -> 30000 | Q9: =_xlfn.XLOOKUP(B9,[1]Sheet1!$B:$B,[1]Sheet1!$T:$T,0) -> 30000 | R9: =_xlfn.XLOOKUP(B9,[1]Sheet1!$B:$B,[1]Sheet1!$U:$U,0) -> 5316 | S9: =_xlfn.XLOOKUP(B9,[1]Sheet1!$B:$B,[1]Sheet1!$V:$V,0) -> 17658 | T9: =_xlfn.XLOOKUP(B9,[1]Sheet1!$B:$B,[1]Sheet1!$W:$W,0) -> 19368 | U9: =_xlfn.XLOOKUP(B9,[1]Sheet1!$B:$B,[1]Sheet1!$X:$X,0) -> 0 | V9: =_xlfn.XLOOKUP(B9,[1]Sheet1!$B:$B,[1]Sheet1!$Y:$Y,0) -> 0 | W9: =SUM(K9:V9) -> 162342 | X9: 451.070205.4511250.1.426427.4510000.200104.000.000000.000000 | Y9: Culture | Z9: DCT - Culture Sites Management Department | AA9: 426427 - Maintenance & repair-Exhibition Stands, etc | AB9: 200104 - FA104-Opex Expense | AC9: Chapter 2 | AD9: 070205 - Cultural site management | AE9: Department of Culture and Tourism | AF9: DCT OPEX Project Type | AG9: 162342 | AH9: =_xlfn.XLOOKUP(B9,[1]Sheet1!$B:$B,[1]Sheet1!$AB:$AB,0) -> 162342
B10: =C10&D10&F10&G10&H10 -> 45112504511000019Admin Expenses-N1421125200104 | C10: 4511250 | D10: 4511000019 | E10: CS-Art Comm-Qatara | F10: Admin Expenses-N1 | G10: 421125 | H10: 200104 | I10: 421125 - Professional Operational Service expenses | J10: APPROVED | K10: =_xlfn.XLOOKUP(B10,[1]Sheet1!$B:$B,[1]Sheet1!$N:$N,0) -> 0 | L10: =_xlfn.XLOOKUP(B10,[1]Sheet1!$B:$B,[1]Sheet1!$O:$O,0) -> 0 | M10: =_xlfn.XLOOKUP(B10,[1]Sheet1!$B:$B,[1]Sheet1!$P:$P,0) -> 0 | N10: =_xlfn.XLOOKUP(B10,[1]Sheet1!$B:$B,[1]Sheet1!$Q:$Q,0) -> 0 | O10: =_xlfn.XLOOKUP(B10,[1]Sheet1!$B:$B,[1]Sheet1!$R:$R,0) -> 40000 | P10: =_xlfn.XLOOKUP(B10,[1]Sheet1!$B:$B,[1]Sheet1!$S:$S,0) -> 40000 | Q10: =_xlfn.XLOOKUP(B10,[1]Sheet1!$B:$B,[1]Sheet1!$T:$T,0) -> 40000 | R10: =_xlfn.XLOOKUP(B10,[1]Sheet1!$B:$B,[1]Sheet1!$U:$U,0) -> 40000 | S10: =_xlfn.XLOOKUP(B10,[1]Sheet1!$B:$B,[1]Sheet1!$V:$V,0) -> 40000 | T10: =_xlfn.XLOOKUP(B10,[1]Sheet1!$B:$B,[1]Sheet1!$W:$W,0) -> 71800 | U10: =_xlfn.XLOOKUP(B10,[1]Sheet1!$B:$B,[1]Sheet1!$X:$X,0) -> 0 | V10: =_xlfn.XLOOKUP(B10,[1]Sheet1!$B:$B,[1]Sheet1!$Y:$Y,0) -> 0 | W10: =SUM(K10:V10) -> 271800 | X10: 451.070205.4511250.1.421125.4510000.200104.000.000000.000000 | Y10: Culture | Z10: DCT - Culture Sites Management Department | AA10: 421125 - Professional Operational Service expenses | AB10: 200104 - FA104-Opex Expense | AC10: Chapter 2 | AD10: 070205 - Cultural site management | AE10: Department of Culture and Tourism | AF10: DCT OPEX Project Type | AG10: 271800 | AH10: =_xlfn.XLOOKUP(B10,[1]Sheet1!$B:$B,[1]Sheet1!$AB:$AB,0) -> 271800
B11: =C11&D11&F11&G11&H11 -> 45112504511000019Art Materials-N1432626200104 | C11: 4511250 | D11: 4511000019 | E11: CS-Art Comm-Qatara | F11: Art Materials-N1 | G11: 432626 | H11: 200104 | I11: 432626 - Music Band related items | J11: APPROVED | K11: =_xlfn.XLOOKUP(B11,[1]Sheet1!$B:$B,[1]Sheet1!$N:$N,0) -> 0 | L11: =_xlfn.XLOOKUP(B11,[1]Sheet1!$B:$B,[1]Sheet1!$O:$O,0) -> 0 | M11: =_xlfn.XLOOKUP(B11,[1]Sheet1!$B:$B,[1]Sheet1!$P:$P,0) -> 0 | N11: =_xlfn.XLOOKUP(B11,[1]Sheet1!$B:$B,[1]Sheet1!$Q:$Q,0) -> 75000 | O11: =_xlfn.XLOOKUP(B11,[1]Sheet1!$B:$B,[1]Sheet1!$R:$R,0) -> 0 | P11: =_xlfn.XLOOKUP(B11,[1]Sheet1!$B:$B,[1]Sheet1!$S:$S,0) -> 50000 | Q11: =_xlfn.XLOOKUP(B11,[1]Sheet1!$B:$B,[1]Sheet1!$T:$T,0) -> 0 | R11: =_xlfn.XLOOKUP(B11,[1]Sheet1!$B:$B,[1]Sheet1!$U:$U,0) -> 0 | S11: =_xlfn.XLOOKUP(B11,[1]Sheet1!$B:$B,[1]Sheet1!$V:$V,0) -> 0 | T11: =_xlfn.XLOOKUP(B11,[1]Sheet1!$B:$B,[1]Sheet1!$W:$W,0) -> 25000 | U11: =_xlfn.XLOOKUP(B11,[1]Sheet1!$B:$B,[1]Sheet1!$X:$X,0) -> 0 | V11: =_xlfn.XLOOKUP(B11,[1]Sheet1!$B:$B,[1]Sheet1!$Y:$Y,0) -> 0 | W11: =SUM(K11:V11) -> 150000 | X11: 451.070205.4511250.1.432626.4510000.200104.000.000000.000000 | Y11: Culture | Z11: DCT - Culture Sites Management Department | AA11: 432626 - Music Band related items | AB11: 200104 - FA104-Opex Expense | AC11: Chapter 2 | AD11: 070205 - Cultural site management | AE11: Department of Culture and Tourism | AF11: DCT OPEX Project Type | AG11: 150000 | AH11: =_xlfn.XLOOKUP(B11,[1]Sheet1!$B:$B,[1]Sheet1!$AB:$AB,0) -> 150000
B12: =C12&D12&F12&G12&H12 -> 45112504511000019Cleaning Service-N422311200104 | C12: 4511250 | D12: 4511000019 | E12: CS-Art Comm-Qatara | F12: Cleaning Service-N | G12: 422311 | H12: 200104 | I12: 422311 - Cleaning Services: Business premises | J12: APPROVED | K12: =_xlfn.XLOOKUP(B12,[1]Sheet1!$B:$B,[1]Sheet1!$N:$N,0) -> 0 | L12: =_xlfn.XLOOKUP(B12,[1]Sheet1!$B:$B,[1]Sheet1!$O:$O,0) -> 0 | M12: =_xlfn.XLOOKUP(B12,[1]Sheet1!$B:$B,[1]Sheet1!$P:$P,0) -> 0 | N12: =_xlfn.XLOOKUP(B12,[1]Sheet1!$B:$B,[1]Sheet1!$Q:$Q,0) -> 45000 | O12: =_xlfn.XLOOKUP(B12,[1]Sheet1!$B:$B,[1]Sheet1!$R:$R,0) -> 15000 | P12: =_xlfn.XLOOKUP(B12,[1]Sheet1!$B:$B,[1]Sheet1!$S:$S,0) -> 15000 | Q12: =_xlfn.XLOOKUP(B12,[1]Sheet1!$B:$B,[1]Sheet1!$T:$T,0) -> 15000 | R12: =_xlfn.XLOOKUP(B12,[1]Sheet1!$B:$B,[1]Sheet1!$U:$U,0) -> 15000 | S12: =_xlfn.XLOOKUP(B12,[1]Sheet1!$B:$B,[1]Sheet1!$V:$V,0) -> 15000 | T12: =_xlfn.XLOOKUP(B12,[1]Sheet1!$B:$B,[1]Sheet1!$W:$W,0) -> 30000 | U12: =_xlfn.XLOOKUP(B12,[1]Sheet1!$B:$B,[1]Sheet1!$X:$X,0) -> 30000 | V12: =_xlfn.XLOOKUP(B12,[1]Sheet1!$B:$B,[1]Sheet1!$Y:$Y,0) -> 38430 | W12: =SUM(K12:V12) -> 218430 | X12: 451.070205.4511250.1.422311.4510000.200104.000.000000.000000 | Y12: Culture | Z12: DCT - Culture Sites Management Department | AA12: 422311 - Cleaning Services: Business premises | AB12: 200104 - FA104-Opex Expense | AC12: Chapter 2 | AD12: 070205 - Cultural site management | AE12: Department of Culture and Tourism | AF12: DCT OPEX Project Type | AG12: 218430 | AH12: =_xlfn.XLOOKUP(B12,[1]Sheet1!$B:$B,[1]Sheet1!$AB:$AB,0) -> 218430
B13: =C13&D13&F13&G13&H13 -> 45112504511000019Freelancers-N424521200104 | C13: 4511250 | D13: 4511000019 | E13: CS-Art Comm-Qatara | F13: Freelancers-N | G13: 424521 | H13: 200104 | I13: 424521 - Manpower supply "Other Than IT Related" | J13: APPROVED | K13: =_xlfn.XLOOKUP(B13,[1]Sheet1!$B:$B,[1]Sheet1!$N:$N,0) -> 0 | L13: =_xlfn.XLOOKUP(B13,[1]Sheet1!$B:$B,[1]Sheet1!$O:$O,0) -> 0 | M13: =_xlfn.XLOOKUP(B13,[1]Sheet1!$B:$B,[1]Sheet1!$P:$P,0) -> 223600 | N13: =_xlfn.XLOOKUP(B13,[1]Sheet1!$B:$B,[1]Sheet1!$Q:$Q,0) -> 71600 | O13: =_xlfn.XLOOKUP(B13,[1]Sheet1!$B:$B,[1]Sheet1!$R:$R,0) -> 98400 | P13: =_xlfn.XLOOKUP(B13,[1]Sheet1!$B:$B,[1]Sheet1!$S:$S,0) -> 98400 | Q13: =_xlfn.XLOOKUP(B13,[1]Sheet1!$B:$B,[1]Sheet1!$T:$T,0) -> 98400 | R13: =_xlfn.XLOOKUP(B13,[1]Sheet1!$B:$B,[1]Sheet1!$U:$U,0) -> 98400 | S13: =_xlfn.XLOOKUP(B13,[1]Sheet1!$B:$B,[1]Sheet1!$V:$V,0) -> 98400 | T13: =_xlfn.XLOOKUP(B13,[1]Sheet1!$B:$B,[1]Sheet1!$W:$W,0) -> 150400 | U13: =_xlfn.XLOOKUP(B13,[1]Sheet1!$B:$B,[1]Sheet1!$X:$X,0) -> 150400 | V13: =_xlfn.XLOOKUP(B13,[1]Sheet1!$B:$B,[1]Sheet1!$Y:$Y,0) -> 150400 | W13: =SUM(K13:V13) -> 1238400 | X13: 451.070205.4511250.1.424521.4510000.200104.000.000000.000000 | Y13: Culture | Z13: DCT - Culture Sites Management Department | AA13: 424521 - Manpower supply Other Than IT Related | AB13: 200104 - FA104-Opex Expense | AC13: Chapter 2 | AD13: 070205 - Cultural site management | AE13: Department of Culture and Tourism | AF13: DCT OPEX Project Type | AG13: 1238400 | AH13: =_xlfn.XLOOKUP(B13,[1]Sheet1!$B:$B,[1]Sheet1!$AB:$AB,0) -> 1238400
B14: =C14&D14&F14&G14&H14 -> 45112504511000019Hospitality-N424761200104 | C14: 4511250 | D14: 4511000019 | E14: CS-Art Comm-Qatara | F14: Hospitality-N | G14: 424761 | H14: 200104 | I14: 424761 - Entertainment and hospitality | J14: APPROVED | K14: =_xlfn.XLOOKUP(B14,[1]Sheet1!$B:$B,[1]Sheet1!$N:$N,0) -> 0 | L14: =_xlfn.XLOOKUP(B14,[1]Sheet1!$B:$B,[1]Sheet1!$O:$O,0) -> 0 | M14: =_xlfn.XLOOKUP(B14,[1]Sheet1!$B:$B,[1]Sheet1!$P:$P,0) -> 0 | N14: =_xlfn.XLOOKUP(B14,[1]Sheet1!$B:$B,[1]Sheet1!$Q:$Q,0) -> 60000 | O14: =_xlfn.XLOOKUP(B14,[1]Sheet1!$B:$B,[1]Sheet1!$R:$R,0) -> 30000 | P14: =_xlfn.XLOOKUP(B14,[1]Sheet1!$B:$B,[1]Sheet1!$S:$S,0) -> 30000 | Q14: =_xlfn.XLOOKUP(B14,[1]Sheet1!$B:$B,[1]Sheet1!$T:$T,0) -> 30000 | R14: =_xlfn.XLOOKUP(B14,[1]Sheet1!$B:$B,[1]Sheet1!$U:$U,0) -> 30000 | S14: =_xlfn.XLOOKUP(B14,[1]Sheet1!$B:$B,[1]Sheet1!$V:$V,0) -> 30000 | T14: =_xlfn.XLOOKUP(B14,[1]Sheet1!$B:$B,[1]Sheet1!$W:$W,0) -> 30000 | U14: =_xlfn.XLOOKUP(B14,[1]Sheet1!$B:$B,[1]Sheet1!$X:$X,0) -> 25000 | V14: =_xlfn.XLOOKUP(B14,[1]Sheet1!$B:$B,[1]Sheet1!$Y:$Y,0) -> 0 | W14: =SUM(K14:V14) -> 265000 | X14: 451.070205.4511250.1.424761.4510000.200104.000.000000.000000 | Y14: Culture | Z14: DCT - Culture Sites Management Department | AA14: 424761 - Entertainment and hospitality | AB14: 200104 - FA104-Opex Expense | AC14: Chapter 2 | AD14: 070205 - Cultural site management | AE14: Department of Culture and Tourism | AF14: DCT OPEX Project Type | AG14: 265000 | AH14: =_xlfn.XLOOKUP(B14,[1]Sheet1!$B:$B,[1]Sheet1!$AB:$AB,0) -> 265000
... B1383: =C1383&D1383&F1383&G1383&H1383 -> 45151004511001730Trade Partners-IO461412402066 | C1383: 4515100 | D1383: 4511001730 | E1383: Kompass TO/TA - HBO | F1383: Trade Partners-IO | G1383: 461412 | H1383: 402066 | I1383: 461412 - Support to AD tourism development program | J1383: APPROVED | K1383: =_xlfn.XLOOKUP(B1383,[1]Sheet1!$B:$B,[1]Sheet1!$N:$N,0) -> 0 | L1383: =_xlfn.XLOOKUP(B1383,[1]Sheet1!$B:$B,[1]Sheet1!$O:$O,0) -> 0 | M1383: =_xlfn.XLOOKUP(B1383,[1]Sheet1!$B:$B,[1]Sheet1!$P:$P,0) -> 0 | N1383: =_xlfn.XLOOKUP(B1383,[1]Sheet1!$B:$B,[1]Sheet1!$Q:$Q,0) -> 0 | O1383: =_xlfn.XLOOKUP(B1383,[1]Sheet1!$B:$B,[1]Sheet1!$R:$R,0) -> 0 | P1383: =_xlfn.XLOOKUP(B1383,[1]Sheet1!$B:$B,[1]Sheet1!$S:$S,0) -> 0 | Q1383: =_xlfn.XLOOKUP(B1383,[1]Sheet1!$B:$B,[1]Sheet1!$T:$T,0) -> 0 | R1383: =_xlfn.XLOOKUP(B1383,[1]Sheet1!$B:$B,[1]Sheet1!$U:$U,0) -> 0 | S1383: =_xlfn.XLOOKUP(B1383,[1]Sheet1!$B:$B,[1]Sheet1!$V:$V,0) -> 0 | T1383: =_xlfn.XLOOKUP(B1383,[1]Sheet1!$B:$B,[1]Sheet1!$W:$W,0) -> 0 | U1383: =_xlfn.XLOOKUP(B1383,[1]Sheet1!$B:$B,[1]Sheet1!$X:$X,0) -> 0 | V1383: =_xlfn.XLOOKUP(B1383,[1]Sheet1!$B:$B,[1]Sheet1!$Y:$Y,0) -> 0 | W1383: =SUM(K1383:V1383) -> 0 | X1383: 451.070503.4515100.1.461412.4510000.402066.000.000000.000000 | Y1383: Tourism | Z1383: DCT-International Operations Department | AA1383: 461412 - Support to AD tourism development program | AB1383: 402066 - FA2066:Tourism Development Program | AC1383: Chapter 4 | AD1383: 070503 - Enhance Visitor Experience | AE1383: Department of Culture and Tourism | AF1383: DCT OPEX Project Type | AG1383: 2098650 | AH1383: =_xlfn.XLOOKUP(B1383,[1]Sheet1!$B:$B,[1]Sheet1!$AB:$AB,0) -> 0
B1384: =C1384&D1384&F1384&G1384&H1384 -> 45102104514000019FZ fees251413000000 | C1384: 4510210 | D1384: 4514000019 | E1384: Free Zone Fees | F1384: FZ fees | G1384: 251413 | H1384: 000000 | I1384: 251413 - Payable to AD GLbl Mrkt | J1384: APPROVED | K1384: =_xlfn.XLOOKUP(B1384,[1]Sheet1!$B:$B,[1]Sheet1!$N:$N,0) -> 0 | L1384: =_xlfn.XLOOKUP(B1384,[1]Sheet1!$B:$B,[1]Sheet1!$O:$O,0) -> 0 | M1384: =_xlfn.XLOOKUP(B1384,[1]Sheet1!$B:$B,[1]Sheet1!$P:$P,0) -> 0 | N1384: =_xlfn.XLOOKUP(B1384,[1]Sheet1!$B:$B,[1]Sheet1!$Q:$Q,0) -> 0 | O1384: =_xlfn.XLOOKUP(B1384,[1]Sheet1!$B:$B,[1]Sheet1!$R:$R,0) -> 0 | P1384: =_xlfn.XLOOKUP(B1384,[1]Sheet1!$B:$B,[1]Sheet1!$S:$S,0) -> 0 | Q1384: =_xlfn.XLOOKUP(B1384,[1]Sheet1!$B:$B,[1]Sheet1!$T:$T,0) -> 0 | R1384: =_xlfn.XLOOKUP(B1384,[1]Sheet1!$B:$B,[1]Sheet1!$U:$U,0) -> 0 | S1384: =_xlfn.XLOOKUP(B1384,[1]Sheet1!$B:$B,[1]Sheet1!$V:$V,0) -> 0 | T1384: =_xlfn.XLOOKUP(B1384,[1]Sheet1!$B:$B,[1]Sheet1!$W:$W,0) -> 0 | U1384: =_xlfn.XLOOKUP(B1384,[1]Sheet1!$B:$B,[1]Sheet1!$X:$X,0) -> 0 | V1384: =_xlfn.XLOOKUP(B1384,[1]Sheet1!$B:$B,[1]Sheet1!$Y:$Y,0) -> 0 | W1384: =SUM(K1384:V1384) -> 0 | X1384: 451.000000.4510210.1.251413.4510000.000000.000.000000.000000 | Y1384: Support Service | Z1384: DCT - Finance Dept | AA1384: 251413 - Long-term Payable to Abu Dhabi Global Market | AB1384: 000000 - Un Specified | AD1384: 000000 - Unspecified | AE1384: Department of Culture and Tourism | AF1384: DCT Trust Project Type | AG1384: 284390.86 | AH1384: =_xlfn.XLOOKUP(B1384,[1]Sheet1!$B:$B,[1]Sheet1!$AB:$AB,0) -> 0
B1385: =C1385&D1385&F1385&G1385&H1385 -> 45110104514000067Admin221390000000 | C1385: 4511010 | D1385: 4514000067 | E1385: DCT Culture Program | F1385: Admin | G1385: 221390 | H1385: 000000 | I1385: 221390 - Other accrued expenses not mentioned elsewhere | J1385: APPROVED | K1385: =_xlfn.XLOOKUP(B1385,[1]Sheet1!$B:$B,[1]Sheet1!$N:$N,0) -> 0 | L1385: =_xlfn.XLOOKUP(B1385,[1]Sheet1!$B:$B,[1]Sheet1!$O:$O,0) -> 0 | M1385: =_xlfn.XLOOKUP(B1385,[1]Sheet1!$B:$B,[1]Sheet1!$P:$P,0) -> 0 | N1385: =_xlfn.XLOOKUP(B1385,[1]Sheet1!$B:$B,[1]Sheet1!$Q:$Q,0) -> 0 | O1385: =_xlfn.XLOOKUP(B1385,[1]Sheet1!$B:$B,[1]Sheet1!$R:$R,0) -> 0 | P1385: =_xlfn.XLOOKUP(B1385,[1]Sheet1!$B:$B,[1]Sheet1!$S:$S,0) -> 0 | Q1385: =_xlfn.XLOOKUP(B1385,[1]Sheet1!$B:$B,[1]Sheet1!$T:$T,0) -> 0 | R1385: =_xlfn.XLOOKUP(B1385,[1]Sheet1!$B:$B,[1]Sheet1!$U:$U,0) -> 0 | S1385: =_xlfn.XLOOKUP(B1385,[1]Sheet1!$B:$B,[1]Sheet1!$V:$V,0) -> 0 | T1385: =_xlfn.XLOOKUP(B1385,[1]Sheet1!$B:$B,[1]Sheet1!$W:$W,0) -> 0 | U1385: =_xlfn.XLOOKUP(B1385,[1]Sheet1!$B:$B,[1]Sheet1!$X:$X,0) -> 0 | V1385: =_xlfn.XLOOKUP(B1385,[1]Sheet1!$B:$B,[1]Sheet1!$Y:$Y,0) -> 0 | W1385: =SUM(K1385:V1385) -> 0 | X1385: 451.000000.4511010.1.221390.4510000.000000.000.000000.000000 | Y1385: Culture | Z1385: DCT - Culture (Central) Dept | AA1385: 221390 - Other accrued expenses not mentioned elsewhere | AB1385: 000000 - Un Specified | AD1385: 000000 - Unspecified | AE1385: Department of Culture and Tourism | AF1385: DCT Trust Project Type | AG1385: 458572.34 | AH1385: =_xlfn.XLOOKUP(B1385,[1]Sheet1!$B:$B,[1]Sheet1!$AB:$AB,0) -> 0
B1386: =C1386&D1386&F1386&G1386&H1386 -> 45110104514000074Event221390000000 | C1386: 4511010 | D1386: 4514000074 | E1386: Mubadala Partnership | F1386: Event | G1386: 221390 | H1386: 000000 | I1386: 221390 - Other accrued expenses not mentioned elsewhere | J1386: APPROVED | K1386: =_xlfn.XLOOKUP(B1386,[1]Sheet1!$B:$B,[1]Sheet1!$N:$N,0) -> 0 | L1386: =_xlfn.XLOOKUP(B1386,[1]Sheet1!$B:$B,[1]Sheet1!$O:$O,0) -> 0 | M1386: =_xlfn.XLOOKUP(B1386,[1]Sheet1!$B:$B,[1]Sheet1!$P:$P,0) -> 0 | N1386: =_xlfn.XLOOKUP(B1386,[1]Sheet1!$B:$B,[1]Sheet1!$Q:$Q,0) -> 0 | O1386: =_xlfn.XLOOKUP(B1386,[1]Sheet1!$B:$B,[1]Sheet1!$R:$R,0) -> 0 | P1386: =_xlfn.XLOOKUP(B1386,[1]Sheet1!$B:$B,[1]Sheet1!$S:$S,0) -> 0 | Q1386: =_xlfn.XLOOKUP(B1386,[1]Sheet1!$B:$B,[1]Sheet1!$T:$T,0) -> 0 | R1386: =_xlfn.XLOOKUP(B1386,[1]Sheet1!$B:$B,[1]Sheet1!$U:$U,0) -> 0 | S1386: =_xlfn.XLOOKUP(B1386,[1]Sheet1!$B:$B,[1]Sheet1!$V:$V,0) -> 0 | T1386: =_xlfn.XLOOKUP(B1386,[1]Sheet1!$B:$B,[1]Sheet1!$W:$W,0) -> 0 | U1386: =_xlfn.XLOOKUP(B1386,[1]Sheet1!$B:$B,[1]Sheet1!$X:$X,0) -> 0 | V1386: =_xlfn.XLOOKUP(B1386,[1]Sheet1!$B:$B,[1]Sheet1!$Y:$Y,0) -> 0 | W1386: =SUM(K1386:V1386) -> 0 | X1386: 451.000000.4511010.1.221390.4510000.000000.000.000000.000000 | Y1386: Culture | Z1386: DCT - Culture (Central) Dept | AA1386: 221390 - Other accrued expenses not mentioned elsewhere | AB1386: 000000 - Un Specified | AD1386: 000000 - Unspecified | AE1386: Department of Culture and Tourism | AF1386: DCT Trust Project Type | AG1386: 326356.58 | AH1386: =_xlfn.XLOOKUP(B1386,[1]Sheet1!$B:$B,[1]Sheet1!$AB:$AB,0) -> 0
B1387: =C1387&D1387&F1387&G1387&H1387 -> 45110104514000074Manpower221390000000 | C1387: 4511010 | D1387: 4514000074 | E1387: Mubadala Partnership | F1387: Manpower | G1387: 221390 | H1387: 000000 | I1387: 221390 - Other accrued expenses not mentioned elsewhere | J1387: APPROVED | K1387: =_xlfn.XLOOKUP(B1387,[1]Sheet1!$B:$B,[1]Sheet1!$N:$N,0) -> 0 | L1387: =_xlfn.XLOOKUP(B1387,[1]Sheet1!$B:$B,[1]Sheet1!$O:$O,0) -> 0 | M1387: =_xlfn.XLOOKUP(B1387,[1]Sheet1!$B:$B,[1]Sheet1!$P:$P,0) -> 0 | N1387: =_xlfn.XLOOKUP(B1387,[1]Sheet1!$B:$B,[1]Sheet1!$Q:$Q,0) -> 0 | O1387: =_xlfn.XLOOKUP(B1387,[1]Sheet1!$B:$B,[1]Sheet1!$R:$R,0) -> 0 | P1387: =_xlfn.XLOOKUP(B1387,[1]Sheet1!$B:$B,[1]Sheet1!$S:$S,0) -> 0 | Q1387: =_xlfn.XLOOKUP(B1387,[1]Sheet1!$B:$B,[1]Sheet1!$T:$T,0) -> 0 | R1387: =_xlfn.XLOOKUP(B1387,[1]Sheet1!$B:$B,[1]Sheet1!$U:$U,0) -> 0 | S1387: =_xlfn.XLOOKUP(B1387,[1]Sheet1!$B:$B,[1]Sheet1!$V:$V,0) -> 0 | T1387: =_xlfn.XLOOKUP(B1387,[1]Sheet1!$B:$B,[1]Sheet1!$W:$W,0) -> 0 | U1387: =_xlfn.XLOOKUP(B1387,[1]Sheet1!$B:$B,[1]Sheet1!$X:$X,0) -> 0 | V1387: =_xlfn.XLOOKUP(B1387,[1]Sheet1!$B:$B,[1]Sheet1!$Y:$Y,0) -> 0 | W1387: =SUM(K1387:V1387) -> 0 | X1387: 451.000000.4511010.1.221390.4510000.000000.000.000000.000000 | Y1387: Culture | Z1387: DCT - Culture (Central) Dept | AA1387: 221390 - Other accrued expenses not mentioned elsewhere | AB1387: 000000 - Un Specified | AD1387: 000000 - Unspecified | AE1387: Department of Culture and Tourism | AF1387: DCT Trust Project Type | AG1387: 17131.579 | AH1387: =_xlfn.XLOOKUP(B1387,[1]Sheet1!$B:$B,[1]Sheet1!$AB:$AB,0) -> 0
B1388: =C1388&D1388&F1388&G1388&H1388 -> 45102104514000078Unidentified221390000000 | C1388: 4510210 | D1388: 4514000078 | E1388: ADEO | F1388: Unidentified | G1388: 221390 | H1388: 000000 | I1388: 221390 - Other accrued expenses not mentioned elsewhere | J1388: APPROVED | K1388: =_xlfn.XLOOKUP(B1388,[1]Sheet1!$B:$B,[1]Sheet1!$N:$N,0) -> 0 | L1388: =_xlfn.XLOOKUP(B1388,[1]Sheet1!$B:$B,[1]Sheet1!$O:$O,0) -> 0 | M1388: =_xlfn.XLOOKUP(B1388,[1]Sheet1!$B:$B,[1]Sheet1!$P:$P,0) -> 0 | N1388: =_xlfn.XLOOKUP(B1388,[1]Sheet1!$B:$B,[1]Sheet1!$Q:$Q,0) -> 0 | O1388: =_xlfn.XLOOKUP(B1388,[1]Sheet1!$B:$B,[1]Sheet1!$R:$R,0) -> 0 | P1388: =_xlfn.XLOOKUP(B1388,[1]Sheet1!$B:$B,[1]Sheet1!$S:$S,0) -> 0 | Q1388: =_xlfn.XLOOKUP(B1388,[1]Sheet1!$B:$B,[1]Sheet1!$T:$T,0) -> 0 | R1388: =_xlfn.XLOOKUP(B1388,[1]Sheet1!$B:$B,[1]Sheet1!$U:$U,0) -> 0 | S1388: =_xlfn.XLOOKUP(B1388,[1]Sheet1!$B:$B,[1]Sheet1!$V:$V,0) -> 0 | T1388: =_xlfn.XLOOKUP(B1388,[1]Sheet1!$B:$B,[1]Sheet1!$W:$W,0) -> 0 | U1388: =_xlfn.XLOOKUP(B1388,[1]Sheet1!$B:$B,[1]Sheet1!$X:$X,0) -> 0 | V1388: =_xlfn.XLOOKUP(B1388,[1]Sheet1!$B:$B,[1]Sheet1!$Y:$Y,0) -> 0 | W1388: =SUM(K1388:V1388) -> 0 | X1388: 451.000000.4510210.1.221390.4510000.000000.000.000000.000000 | Y1388: Support Service | Z1388: DCT - Finance Dept | AA1388: 221390 - Other accrued expenses not mentioned elsewhere | AB1388: 000000 - Un Specified | AD1388: 000000 - Unspecified | AE1388: Department of Culture and Tourism | AF1388: DCT Trust Project Type | AG1388: 6632.8358 | AH1388: =_xlfn.XLOOKUP(B1388,[1]Sheet1!$B:$B,[1]Sheet1!$AB:$AB,0) -> 0
B1389: =C1389&D1389&F1389&G1389&H1389 -> 45102104514000084Event Management221390000000 | C1389: 4510210 | D1389: 4514000084 | E1389: My story world | F1389: Event Management | G1389: 221390 | H1389: 000000 | I1389: 221390 - Other accrued expenses not mentioned elsewhere | J1389: APPROVED | K1389: =_xlfn.XLOOKUP(B1389,[1]Sheet1!$B:$B,[1]Sheet1!$N:$N,0) -> 0 | L1389: =_xlfn.XLOOKUP(B1389,[1]Sheet1!$B:$B,[1]Sheet1!$O:$O,0) -> 0 | M1389: =_xlfn.XLOOKUP(B1389,[1]Sheet1!$B:$B,[1]Sheet1!$P:$P,0) -> 0 | N1389: =_xlfn.XLOOKUP(B1389,[1]Sheet1!$B:$B,[1]Sheet1!$Q:$Q,0) -> 0 | O1389: =_xlfn.XLOOKUP(B1389,[1]Sheet1!$B:$B,[1]Sheet1!$R:$R,0) -> 0 | P1389: =_xlfn.XLOOKUP(B1389,[1]Sheet1!$B:$B,[1]Sheet1!$S:$S,0) -> 0 | Q1389: =_xlfn.XLOOKUP(B1389,[1]Sheet1!$B:$B,[1]Sheet1!$T:$T,0) -> 0 | R1389: =_xlfn.XLOOKUP(B1389,[1]Sheet1!$B:$B,[1]Sheet1!$U:$U,0) -> 0 | S1389: =_xlfn.XLOOKUP(B1389,[1]Sheet1!$B:$B,[1]Sheet1!$V:$V,0) -> 0 | T1389: =_xlfn.XLOOKUP(B1389,[1]Sheet1!$B:$B,[1]Sheet1!$W:$W,0) -> 0 | U1389: =_xlfn.XLOOKUP(B1389,[1]Sheet1!$B:$B,[1]Sheet1!$X:$X,0) -> 0 | V1389: =_xlfn.XLOOKUP(B1389,[1]Sheet1!$B:$B,[1]Sheet1!$Y:$Y,0) -> 0 | W1389: =SUM(K1389:V1389) -> 0 | X1389: 451.000000.4510210.1.221390.4510000.000000.000.000000.000000 | Y1389: Support Service | Z1389: DCT - Finance Dept | AA1389: 221390 - Other accrued expenses not mentioned elsewhere | AB1389: 000000 - Un Specified | AD1389: 000000 - Unspecified | AE1389: Department of Culture and Tourism | AF1389: DCT Trust Project Type | AG1389: 910360.88 | AH1389: =_xlfn.XLOOKUP(B1389,[1]Sheet1!$B:$B,[1]Sheet1!$AB:$AB,0) -> 0
B1390: =C1390&D1390&F1390&G1390&H1390 -> 45102104514000086Euro League221390000000 | C1390: 4510210 | D1390: 4514000086 | E1390: Yas Bay Arena | F1390: Euro League | G1390: 221390 | H1390: 000000 | I1390: 221390 - Other accrued expenses not mentioned elsewhere | J1390: APPROVED | K1390: =_xlfn.XLOOKUP(B1390,[1]Sheet1!$B:$B,[1]Sheet1!$N:$N,0) -> 0 | L1390: =_xlfn.XLOOKUP(B1390,[1]Sheet1!$B:$B,[1]Sheet1!$O:$O,0) -> 0 | M1390: =_xlfn.XLOOKUP(B1390,[1]Sheet1!$B:$B,[1]Sheet1!$P:$P,0) -> 0 | N1390: =_xlfn.XLOOKUP(B1390,[1]Sheet1!$B:$B,[1]Sheet1!$Q:$Q,0) -> 0 | O1390: =_xlfn.XLOOKUP(B1390,[1]Sheet1!$B:$B,[1]Sheet1!$R:$R,0) -> 0 | P1390: =_xlfn.XLOOKUP(B1390,[1]Sheet1!$B:$B,[1]Sheet1!$S:$S,0) -> 0 | Q1390: =_xlfn.XLOOKUP(B1390,[1]Sheet1!$B:$B,[1]Sheet1!$T:$T,0) -> 0 | R1390: =_xlfn.XLOOKUP(B1390,[1]Sheet1!$B:$B,[1]Sheet1!$U:$U,0) -> 0 | S1390: =_xlfn.XLOOKUP(B1390,[1]Sheet1!$B:$B,[1]Sheet1!$V:$V,0) -> 0 | T1390: =_xlfn.XLOOKUP(B1390,[1]Sheet1!$B:$B,[1]Sheet1!$W:$W,0) -> 0 | U1390: =_xlfn.XLOOKUP(B1390,[1]Sheet1!$B:$B,[1]Sheet1!$X:$X,0) -> 0 | V1390: =_xlfn.XLOOKUP(B1390,[1]Sheet1!$B:$B,[1]Sheet1!$Y:$Y,0) -> 0 | W1390: =SUM(K1390:V1390) -> 0 | X1390: 451.000000.4510210.1.221390.4510000.000000.000.000000.000000 | Y1390: Support Service | Z1390: DCT - Finance Dept | AA1390: 221390 - Other accrued expenses not mentioned elsewhere | AB1390: 000000 - Un Specified | AD1390: 000000 - Unspecified | AE1390: Department of Culture and Tourism | AF1390: DCT Trust Project Type | AG1390: 3024664.2 | AH1390: =_xlfn.XLOOKUP(B1390,[1]Sheet1!$B:$B,[1]Sheet1!$AB:$AB,0) -> 0
B1391: =C1391&D1391&F1391&G1391&H1391 -> 45102104514000087Extend Stay221390000000 | C1391: 4510210 | D1391: 4514000087 | E1391: Hotel Payments | F1391: Extend Stay | G1391: 221390 | H1391: 000000 | I1391: 221390 - Other accrued expenses not mentioned elsewhere | J1391: APPROVED | K1391: =_xlfn.XLOOKUP(B1391,[1]Sheet1!$B:$B,[1]Sheet1!$N:$N,0) -> 0 | L1391: =_xlfn.XLOOKUP(B1391,[1]Sheet1!$B:$B,[1]Sheet1!$O:$O,0) -> 0 | M1391: =_xlfn.XLOOKUP(B1391,[1]Sheet1!$B:$B,[1]Sheet1!$P:$P,0) -> 0 | N1391: =_xlfn.XLOOKUP(B1391,[1]Sheet1!$B:$B,[1]Sheet1!$Q:$Q,0) -> 0 | O1391: =_xlfn.XLOOKUP(B1391,[1]Sheet1!$B:$B,[1]Sheet1!$R:$R,0) -> 0 | P1391: =_xlfn.XLOOKUP(B1391,[1]Sheet1!$B:$B,[1]Sheet1!$S:$S,0) -> 0 | Q1391: =_xlfn.XLOOKUP(B1391,[1]Sheet1!$B:$B,[1]Sheet1!$T:$T,0) -> 0 | R1391: =_xlfn.XLOOKUP(B1391,[1]Sheet1!$B:$B,[1]Sheet1!$U:$U,0) -> 0 | S1391: =_xlfn.XLOOKUP(B1391,[1]Sheet1!$B:$B,[1]Sheet1!$V:$V,0) -> 0 | T1391: =_xlfn.XLOOKUP(B1391,[1]Sheet1!$B:$B,[1]Sheet1!$W:$W,0) -> 0 | U1391: =_xlfn.XLOOKUP(B1391,[1]Sheet1!$B:$B,[1]Sheet1!$X:$X,0) -> 0 | V1391: =_xlfn.XLOOKUP(B1391,[1]Sheet1!$B:$B,[1]Sheet1!$Y:$Y,0) -> 0 | W1391: =SUM(K1391:V1391) -> 0 | X1391: 451.000000.4510210.1.221390.4510000.000000.000.000000.000000 | Y1391: Support Service | Z1391: DCT - Finance Dept | AA1391: 221390 - Other accrued expenses not mentioned elsewhere | AB1391: 000000 - Un Specified | AD1391: 000000 - Unspecified | AE1391: Department of Culture and Tourism | AF1391: DCT Trust Project Type | AG1391: 4794941.1 | AH1391: =_xlfn.XLOOKUP(B1391,[1]Sheet1!$B:$B,[1]Sheet1!$AB:$AB,0) -> 0
B1392: =C1392&D1392&F1392&G1392&H1392 -> 45102104514000087Privet Host221390000000 | C1392: 4510210 | D1392: 4514000087 | E1392: Hotel Payments | F1392: Privet Host | G1392: 221390 | H1392: 000000 | I1392: 221390 - Other accrued expenses not mentioned elsewhere | J1392: APPROVED | K1392: =_xlfn.XLOOKUP(B1392,[1]Sheet1!$B:$B,[1]Sheet1!$N:$N,0) -> 0 | L1392: =_xlfn.XLOOKUP(B1392,[1]Sheet1!$B:$B,[1]Sheet1!$O:$O,0) -> 0 | M1392: =_xlfn.XLOOKUP(B1392,[1]Sheet1!$B:$B,[1]Sheet1!$P:$P,0) -> 0 | N1392: =_xlfn.XLOOKUP(B1392,[1]Sheet1!$B:$B,[1]Sheet1!$Q:$Q,0) -> 0 | O1392: =_xlfn.XLOOKUP(B1392,[1]Sheet1!$B:$B,[1]Sheet1!$R:$R,0) -> 0 | P1392: =_xlfn.XLOOKUP(B1392,[1]Sheet1!$B:$B,[1]Sheet1!$S:$S,0) -> 0 | Q1392: =_xlfn.XLOOKUP(B1392,[1]Sheet1!$B:$B,[1]Sheet1!$T:$T,0) -> 0 | R1392: =_xlfn.XLOOKUP(B1392,[1]Sheet1!$B:$B,[1]Sheet1!$U:$U,0) -> 0 | S1392: =_xlfn.XLOOKUP(B1392,[1]Sheet1!$B:$B,[1]Sheet1!$V:$V,0) -> 0 | T1392: =_xlfn.XLOOKUP(B1392,[1]Sheet1!$B:$B,[1]Sheet1!$W:$W,0) -> 0 | U1392: =_xlfn.XLOOKUP(B1392,[1]Sheet1!$B:$B,[1]Sheet1!$X:$X,0) -> 0 | V1392: =_xlfn.XLOOKUP(B1392,[1]Sheet1!$B:$B,[1]Sheet1!$Y:$Y,0) -> 0 | W1392: =SUM(K1392:V1392) -> 0 | X1392: 451.000000.4510210.1.221390.4510000.000000.000.000000.000000 | Y1392: Support Service | Z1392: DCT - Finance Dept | AA1392: 221390 - Other accrued expenses not mentioned elsewhere | AB1392: 000000 - Un Specified | AD1392: 000000 - Unspecified | AE1392: Department of Culture and Tourism | AF1392: DCT Trust Project Type | AG1392: 97526743 | AH1392: =_xlfn.XLOOKUP(B1392,[1]Sheet1!$B:$B,[1]Sheet1!$AB:$AB,0) -> 0
B1393: =C1393&D1393&F1393&G1393&H1393 -> 45110104514000088CPC221390000000 | C1393: 4511010 | D1393: 4514000088 | E1393: ADMAF - Trust | F1393: CPC | G1393: 221390 | H1393: 000000 | I1393: 221390 - Other accrued expenses not mentioned elsewhere | J1393: APPROVED | K1393: =_xlfn.XLOOKUP(B1393,[1]Sheet1!$B:$B,[1]Sheet1!$N:$N,0) -> 0 | L1393: =_xlfn.XLOOKUP(B1393,[1]Sheet1!$B:$B,[1]Sheet1!$O:$O,0) -> 0 | M1393: =_xlfn.XLOOKUP(B1393,[1]Sheet1!$B:$B,[1]Sheet1!$P:$P,0) -> 0 | N1393: =_xlfn.XLOOKUP(B1393,[1]Sheet1!$B:$B,[1]Sheet1!$Q:$Q,0) -> 0 | O1393: =_xlfn.XLOOKUP(B1393,[1]Sheet1!$B:$B,[1]Sheet1!$R:$R,0) -> 0 | P1393: =_xlfn.XLOOKUP(B1393,[1]Sheet1!$B:$B,[1]Sheet1!$S:$S,0) -> 0 | Q1393: =_xlfn.XLOOKUP(B1393,[1]Sheet1!$B:$B,[1]Sheet1!$T:$T,0) -> 0 | R1393: =_xlfn.XLOOKUP(B1393,[1]Sheet1!$B:$B,[1]Sheet1!$U:$U,0) -> 0 | S1393: =_xlfn.XLOOKUP(B1393,[1]Sheet1!$B:$B,[1]Sheet1!$V:$V,0) -> 0 | T1393: =_xlfn.XLOOKUP(B1393,[1]Sheet1!$B:$B,[1]Sheet1!$W:$W,0) -> 0 | U1393: =_xlfn.XLOOKUP(B1393,[1]Sheet1!$B:$B,[1]Sheet1!$X:$X,0) -> 0 | V1393: =_xlfn.XLOOKUP(B1393,[1]Sheet1!$B:$B,[1]Sheet1!$Y:$Y,0) -> 0 | W1393: =SUM(K1393:V1393) -> 0 | X1393: 451.000000.4511010.1.221390.4510000.000000.000.000000.000000 | Y1393: Culture | Z1393: DCT - Culture (Central) Dept | AA1393: 221390 - Other accrued expenses not mentioned elsewhere | AB1393: 000000 - Un Specified | AD1393: 000000 - Unspecified | AE1393: Department of Culture and Tourism | AF1393: DCT Trust Project Type | AG1393: 1610677.9 | AH1393: =_xlfn.XLOOKUP(B1393,[1]Sheet1!$B:$B,[1]Sheet1!$AB:$AB,0) -> 0
B1394: =C1394&D1394&F1394&G1394&H1394 -> 45155004514000089Sponsorship Fees221390000000 | C1394: 4515500 | D1394: 4514000089 | E1394: ADSS - Hyrox | F1394: Sponsorship Fees | G1394: 221390 | H1394: 000000 | I1394: 221390 - Other accrued expenses not mentioned elsewhere | J1394: APPROVED | K1394: =_xlfn.XLOOKUP(B1394,[1]Sheet1!$B:$B,[1]Sheet1!$N:$N,0) -> 0 | L1394: =_xlfn.XLOOKUP(B1394,[1]Sheet1!$B:$B,[1]Sheet1!$O:$O,0) -> 0 | M1394: =_xlfn.XLOOKUP(B1394,[1]Sheet1!$B:$B,[1]Sheet1!$P:$P,0) -> 0 | N1394: =_xlfn.XLOOKUP(B1394,[1]Sheet1!$B:$B,[1]Sheet1!$Q:$Q,0) -> 0 | O1394: =_xlfn.XLOOKUP(B1394,[1]Sheet1!$B:$B,[1]Sheet1!$R:$R,0) -> 0 | P1394: =_xlfn.XLOOKUP(B1394,[1]Sheet1!$B:$B,[1]Sheet1!$S:$S,0) -> 0 | Q1394: =_xlfn.XLOOKUP(B1394,[1]Sheet1!$B:$B,[1]Sheet1!$T:$T,0) -> 0 | R1394: =_xlfn.XLOOKUP(B1394,[1]Sheet1!$B:$B,[1]Sheet1!$U:$U,0) -> 0 | S1394: =_xlfn.XLOOKUP(B1394,[1]Sheet1!$B:$B,[1]Sheet1!$V:$V,0) -> 0 | T1394: =_xlfn.XLOOKUP(B1394,[1]Sheet1!$B:$B,[1]Sheet1!$W:$W,0) -> 0 | U1394: =_xlfn.XLOOKUP(B1394,[1]Sheet1!$B:$B,[1]Sheet1!$X:$X,0) -> 0 | V1394: =_xlfn.XLOOKUP(B1394,[1]Sheet1!$B:$B,[1]Sheet1!$Y:$Y,0) -> 0 | W1394: =SUM(K1394:V1394) -> 0 | X1394: 451.000000.4515500.1.221390.4510000.000000.000.000000.000000 | Y1394: Tourism | Z1394: DCT - Abu Dhabi Events Bureau | AA1394: 221390 - Other accrued expenses not mentioned elsewhere | AB1394: 000000 - Un Specified | AD1394: 000000 - Unspecified | AE1394: Department of Culture and Tourism | AF1394: DCT Trust Project Type | AG1394: 794689.2 | AH1394: =_xlfn.XLOOKUP(B1394,[1]Sheet1!$B:$B,[1]Sheet1!$AB:$AB,0) -> 0
B1395: =C1395&D1395&F1395&G1395&H1395 -> 451400045170000014510789424521200104 | C1395: 4514000 | D1395: 4517000001 | E1395: Museums - Director's Office | F1395: 4510789 | G1395: 424521 | H1395: 200104 | I1395: 424521 - Manpower supply Other Than IT Related | J1395: APPROVED | K1395: =_xlfn.XLOOKUP(B1395,[1]Sheet1!$B:$B,[1]Sheet1!$N:$N,0) -> 0 | L1395: =_xlfn.XLOOKUP(B1395,[1]Sheet1!$B:$B,[1]Sheet1!$O:$O,0) -> 0 | M1395: =_xlfn.XLOOKUP(B1395,[1]Sheet1!$B:$B,[1]Sheet1!$P:$P,0) -> 0 | N1395: =_xlfn.XLOOKUP(B1395,[1]Sheet1!$B:$B,[1]Sheet1!$Q:$Q,0) -> 0 | O1395: =_xlfn.XLOOKUP(B1395,[1]Sheet1!$B:$B,[1]Sheet1!$R:$R,0) -> 0 | P1395: =_xlfn.XLOOKUP(B1395,[1]Sheet1!$B:$B,[1]Sheet1!$S:$S,0) -> 0 | Q1395: =_xlfn.XLOOKUP(B1395,[1]Sheet1!$B:$B,[1]Sheet1!$T:$T,0) -> 0 | R1395: =_xlfn.XLOOKUP(B1395,[1]Sheet1!$B:$B,[1]Sheet1!$U:$U,0) -> 0 | S1395: =_xlfn.XLOOKUP(B1395,[1]Sheet1!$B:$B,[1]Sheet1!$V:$V,0) -> 0 | T1395: =_xlfn.XLOOKUP(B1395,[1]Sheet1!$B:$B,[1]Sheet1!$W:$W,0) -> 0 | U1395: =_xlfn.XLOOKUP(B1395,[1]Sheet1!$B:$B,[1]Sheet1!$X:$X,0) -> 0 | V1395: =_xlfn.XLOOKUP(B1395,[1]Sheet1!$B:$B,[1]Sheet1!$Y:$Y,0) -> 0 | W1395: =SUM(K1395:V1395) -> 0 | X1395: 451.070101.4514000.1.424521.4510700.200104.000.000000.000000 | Y1395: Museum Shared Services | Z1395: Museums - Director’s Office | AA1395: 424521 - Manpower supply Other Than IT Related | AB1395: 200104 - FA104-Opex Expense | AC1395: Chapter 2 | AD1395: 070101 - Corporate Office | AE1395: Museum Shared Services | AF1395: MSS OPEX Project Type | AG1395: 420000 | AH1395: =_xlfn.XLOOKUP(B1395,[1]Sheet1!$B:$B,[1]Sheet1!$AB:$AB,0) -> 0
B1396: =C1396&D1396&F1396&G1396&H1396 -> 451400045170000014510808421122200104 | C1396: 4514000 | D1396: 4517000001 | E1396: Museums - Director's Office | F1396: 4510808 | G1396: 421122 | H1396: 200104 | I1396: 421122 - Management consultancy expenses | J1396: APPROVED | K1396: =_xlfn.XLOOKUP(B1396,[1]Sheet1!$B:$B,[1]Sheet1!$N:$N,0) -> 0 | L1396: =_xlfn.XLOOKUP(B1396,[1]Sheet1!$B:$B,[1]Sheet1!$O:$O,0) -> 0 | M1396: =_xlfn.XLOOKUP(B1396,[1]Sheet1!$B:$B,[1]Sheet1!$P:$P,0) -> 0 | N1396: =_xlfn.XLOOKUP(B1396,[1]Sheet1!$B:$B,[1]Sheet1!$Q:$Q,0) -> 0 | O1396: =_xlfn.XLOOKUP(B1396,[1]Sheet1!$B:$B,[1]Sheet1!$R:$R,0) -> 0 | P1396: =_xlfn.XLOOKUP(B1396,[1]Sheet1!$B:$B,[1]Sheet1!$S:$S,0) -> 0 | Q1396: =_xlfn.XLOOKUP(B1396,[1]Sheet1!$B:$B,[1]Sheet1!$T:$T,0) -> 0 | R1396: =_xlfn.XLOOKUP(B1396,[1]Sheet1!$B:$B,[1]Sheet1!$U:$U,0) -> 0 | S1396: =_xlfn.XLOOKUP(B1396,[1]Sheet1!$B:$B,[1]Sheet1!$V:$V,0) -> 0 | T1396: =_xlfn.XLOOKUP(B1396,[1]Sheet1!$B:$B,[1]Sheet1!$W:$W,0) -> 0 | U1396: =_xlfn.XLOOKUP(B1396,[1]Sheet1!$B:$B,[1]Sheet1!$X:$X,0) -> 0 | V1396: =_xlfn.XLOOKUP(B1396,[1]Sheet1!$B:$B,[1]Sheet1!$Y:$Y,0) -> 0 | W1396: =SUM(K1396:V1396) -> 0 | X1396: 451.070101.4514000.1.421122.4510700.200104.000.000000.000000 | Y1396: Museum Shared Services | Z1396: Museums - Director’s Office | AA1396: 421122 - Management consultancy expenses | AB1396: 200104 - FA104-Opex Expense | AC1396: Chapter 2 | AD1396: 070101 - Corporate Office | AE1396: Museum Shared Services | AF1396: MSS OPEX Project Type | AG1396: 525000 | AH1396: =_xlfn.XLOOKUP(B1396,[1]Sheet1!$B:$B,[1]Sheet1!$AB:$AB,0) -> 0
B1397: =C1397&D1397&F1397&G1397&H1397 -> 451412045170000024510723424521200104 | C1397: 4514120 | D1397: 4517000002 | E1397: Museums - Finance Planning and Business Partnership | F1397: 4510723 | G1397: 424521 | H1397: 200104 | I1397: 424521 - Manpower supply Other Than IT Related | J1397: APPROVED | K1397: =_xlfn.XLOOKUP(B1397,[1]Sheet1!$B:$B,[1]Sheet1!$N:$N,0) -> 0 | L1397: =_xlfn.XLOOKUP(B1397,[1]Sheet1!$B:$B,[1]Sheet1!$O:$O,0) -> 0 | M1397: =_xlfn.XLOOKUP(B1397,[1]Sheet1!$B:$B,[1]Sheet1!$P:$P,0) -> 0 | N1397: =_xlfn.XLOOKUP(B1397,[1]Sheet1!$B:$B,[1]Sheet1!$Q:$Q,0) -> 0 | O1397: =_xlfn.XLOOKUP(B1397,[1]Sheet1!$B:$B,[1]Sheet1!$R:$R,0) -> 0 | P1397: =_xlfn.XLOOKUP(B1397,[1]Sheet1!$B:$B,[1]Sheet1!$S:$S,0) -> 0 | Q1397: =_xlfn.XLOOKUP(B1397,[1]Sheet1!$B:$B,[1]Sheet1!$T:$T,0) -> 0 | R1397: =_xlfn.XLOOKUP(B1397,[1]Sheet1!$B:$B,[1]Sheet1!$U:$U,0) -> 0 | S1397: =_xlfn.XLOOKUP(B1397,[1]Sheet1!$B:$B,[1]Sheet1!$V:$V,0) -> 0 | T1397: =_xlfn.XLOOKUP(B1397,[1]Sheet1!$B:$B,[1]Sheet1!$W:$W,0) -> 0 | U1397: =_xlfn.XLOOKUP(B1397,[1]Sheet1!$B:$B,[1]Sheet1!$X:$X,0) -> 0 | V1397: =_xlfn.XLOOKUP(B1397,[1]Sheet1!$B:$B,[1]Sheet1!$Y:$Y,0) -> 0 | W1397: =SUM(K1397:V1397) -> 0 | X1397: 451.070103.4514120.1.424521.4510700.200104.000.000000.000000 | Y1397: Museum Shared Services | Z1397: Museums - Finance | AA1397: 424521 - Manpower supply Other Than IT Related | AB1397: 200104 - FA104-Opex Expense | AC1397: Chapter 2 | AD1397: 070103 - Human Resource (HR) | AE1397: Museum Shared Services | AF1397: MSS OPEX Project Type | AG1397: 774000 | AH1397: =_xlfn.XLOOKUP(B1397,[1]Sheet1!$B:$B,[1]Sheet1!$AB:$AB,0) -> 0
B1398: =C1398&D1398&F1398&G1398&H1398 -> 451412045170000034510715437111200104 | C1398: 4514120 | D1398: 4517000003 | E1398: Museums - Finance Operations | F1398: 4510715 | G1398: 437111 | H1398: 200104 | I1398: 437111 - Banking service charges | J1398: APPROVED | K1398: =_xlfn.XLOOKUP(B1398,[1]Sheet1!$B:$B,[1]Sheet1!$N:$N,0) -> 0 | L1398: =_xlfn.XLOOKUP(B1398,[1]Sheet1!$B:$B,[1]Sheet1!$O:$O,0) -> 0 | M1398: =_xlfn.XLOOKUP(B1398,[1]Sheet1!$B:$B,[1]Sheet1!$P:$P,0) -> 0 | N1398: =_xlfn.XLOOKUP(B1398,[1]Sheet1!$B:$B,[1]Sheet1!$Q:$Q,0) -> 0 | O1398: =_xlfn.XLOOKUP(B1398,[1]Sheet1!$B:$B,[1]Sheet1!$R:$R,0) -> 0 | P1398: =_xlfn.XLOOKUP(B1398,[1]Sheet1!$B:$B,[1]Sheet1!$S:$S,0) -> 0 | Q1398: =_xlfn.XLOOKUP(B1398,[1]Sheet1!$B:$B,[1]Sheet1!$T:$T,0) -> 0 | R1398: =_xlfn.XLOOKUP(B1398,[1]Sheet1!$B:$B,[1]Sheet1!$U:$U,0) -> 0 | S1398: =_xlfn.XLOOKUP(B1398,[1]Sheet1!$B:$B,[1]Sheet1!$V:$V,0) -> 0 | T1398: =_xlfn.XLOOKUP(B1398,[1]Sheet1!$B:$B,[1]Sheet1!$W:$W,0) -> 0 | U1398: =_xlfn.XLOOKUP(B1398,[1]Sheet1!$B:$B,[1]Sheet1!$X:$X,0) -> 0 | V1398: =_xlfn.XLOOKUP(B1398,[1]Sheet1!$B:$B,[1]Sheet1!$Y:$Y,0) -> 0 | W1398: =SUM(K1398:V1398) -> 0 | X1398: 451.070102.4514120.1.437111.4510700.200104.000.000000.000000 | Y1398: Museum Shared Services | Z1398: Museums - Finance | AA1398: 437111 - Banking service charges | AB1398: 200104 - FA104-Opex Expense | AC1398: Chapter 2 | AD1398: 070102 - Finance | AE1398: Museum Shared Services | AF1398: MSS OPEX Project Type | AG1398: 3063927 | AH1398: =_xlfn.XLOOKUP(B1398,[1]Sheet1!$B:$B,[1]Sheet1!$AB:$AB,0) -> 0
B1399: =C1399&D1399&F1399&G1399&H1399 -> 451412045170000034510720421112200104 | C1399: 4514120 | D1399: 4517000003 | E1399: Museums - Finance Operations | F1399: 4510720 | G1399: 421112 | H1399: 200104 | I1399: 421112 - Internal Audit service expenses | J1399: APPROVED | K1399: =_xlfn.XLOOKUP(B1399,[1]Sheet1!$B:$B,[1]Sheet1!$N:$N,0) -> 0 | L1399: =_xlfn.XLOOKUP(B1399,[1]Sheet1!$B:$B,[1]Sheet1!$O:$O,0) -> 0 | M1399: =_xlfn.XLOOKUP(B1399,[1]Sheet1!$B:$B,[1]Sheet1!$P:$P,0) -> 0 | N1399: =_xlfn.XLOOKUP(B1399,[1]Sheet1!$B:$B,[1]Sheet1!$Q:$Q,0) -> 0 | O1399: =_xlfn.XLOOKUP(B1399,[1]Sheet1!$B:$B,[1]Sheet1!$R:$R,0) -> 0 | P1399: =_xlfn.XLOOKUP(B1399,[1]Sheet1!$B:$B,[1]Sheet1!$S:$S,0) -> 0 | Q1399: =_xlfn.XLOOKUP(B1399,[1]Sheet1!$B:$B,[1]Sheet1!$T:$T,0) -> 0 | R1399: =_xlfn.XLOOKUP(B1399,[1]Sheet1!$B:$B,[1]Sheet1!$U:$U,0) -> 0 | S1399: =_xlfn.XLOOKUP(B1399,[1]Sheet1!$B:$B,[1]Sheet1!$V:$V,0) -> 0 | T1399: =_xlfn.XLOOKUP(B1399,[1]Sheet1!$B:$B,[1]Sheet1!$W:$W,0) -> 0 | U1399: =_xlfn.XLOOKUP(B1399,[1]Sheet1!$B:$B,[1]Sheet1!$X:$X,0) -> 0 | V1399: =_xlfn.XLOOKUP(B1399,[1]Sheet1!$B:$B,[1]Sheet1!$Y:$Y,0) -> 0 | W1399: =SUM(K1399:V1399) -> 0 | X1399: 451.070102.4514120.1.421112.4510700.200104.000.000000.000000 | Y1399: Museum Shared Services | Z1399: Museums - Finance | AA1399: 421112 - Internal Audit service expenses | AB1399: 200104 - FA104-Opex Expense | AC1399: Chapter 2 | AD1399: 070102 - Finance | AE1399: Museum Shared Services | AF1399: MSS OPEX Project Type | AG1399: 1291794 | AH1399: =_xlfn.XLOOKUP(B1399,[1]Sheet1!$B:$B,[1]Sheet1!$AB:$AB,0) -> 0
B1400: =C1400&D1400&F1400&G1400&H1400 -> 451412045170000044510723424521200104 | C1400: 4514120 | D1400: 4517000004 | E1400: Museums - Payables Operations | F1400: 4510723 | G1400: 424521 | H1400: 200104 | I1400: 424521 - Manpower supply Other Than IT Related | J1400: APPROVED | K1400: =_xlfn.XLOOKUP(B1400,[1]Sheet1!$B:$B,[1]Sheet1!$N:$N,0) -> 0 | L1400: =_xlfn.XLOOKUP(B1400,[1]Sheet1!$B:$B,[1]Sheet1!$O:$O,0) -> 0 | M1400: =_xlfn.XLOOKUP(B1400,[1]Sheet1!$B:$B,[1]Sheet1!$P:$P,0) -> 0 | N1400: =_xlfn.XLOOKUP(B1400,[1]Sheet1!$B:$B,[1]Sheet1!$Q:$Q,0) -> 0 | O1400: =_xlfn.XLOOKUP(B1400,[1]Sheet1!$B:$B,[1]Sheet1!$R:$R,0) -> 0 | P1400: =_xlfn.XLOOKUP(B1400,[1]Sheet1!$B:$B,[1]Sheet1!$S:$S,0) -> 0 | Q1400: =_xlfn.XLOOKUP(B1400,[1]Sheet1!$B:$B,[1]Sheet1!$T:$T,0) -> 0 | R1400: =_xlfn.XLOOKUP(B1400,[1]Sheet1!$B:$B,[1]Sheet1!$U:$U,0) -> 0 | S1400: =_xlfn.XLOOKUP(B1400,[1]Sheet1!$B:$B,[1]Sheet1!$V:$V,0) -> 0 | T1400: =_xlfn.XLOOKUP(B1400,[1]Sheet1!$B:$B,[1]Sheet1!$W:$W,0) -> 0 | U1400: =_xlfn.XLOOKUP(B1400,[1]Sheet1!$B:$B,[1]Sheet1!$X:$X,0) -> 0 | V1400: =_xlfn.XLOOKUP(B1400,[1]Sheet1!$B:$B,[1]Sheet1!$Y:$Y,0) -> 0 | W1400: =SUM(K1400:V1400) -> 0 | X1400: 451.070103.4514120.1.424521.4510700.200104.000.000000.000000 | Y1400: Museum Shared Services | Z1400: Museums - Finance | AA1400: 424521 - Manpower supply Other Than IT Related | AB1400: 200104 - FA104-Opex Expense | AC1400: Chapter 2 | AD1400: 070103 - Human Resource (HR) | AE1400: Museum Shared Services | AF1400: MSS OPEX Project Type | AG1400: 660000 | AH1400: =_xlfn.XLOOKUP(B1400,[1]Sheet1!$B:$B,[1]Sheet1!$AB:$AB,0) -> 0
B1401: =C1401&D1401&F1401&G1401&H1401 -> 451412045170000054510723424521200104 | C1401: 4514120 | D1401: 4517000005 | E1401: Museums - Receivables Operations | F1401: 4510723 | G1401: 424521 | H1401: 200104 | I1401: 424521 - Manpower supply Other Than IT Related | J1401: APPROVED | K1401: =_xlfn.XLOOKUP(B1401,[1]Sheet1!$B:$B,[1]Sheet1!$N:$N,0) -> 0 | L1401: =_xlfn.XLOOKUP(B1401,[1]Sheet1!$B:$B,[1]Sheet1!$O:$O,0) -> 0 | M1401: =_xlfn.XLOOKUP(B1401,[1]Sheet1!$B:$B,[1]Sheet1!$P:$P,0) -> 0 | N1401: =_xlfn.XLOOKUP(B1401,[1]Sheet1!$B:$B,[1]Sheet1!$Q:$Q,0) -> 0 | O1401: =_xlfn.XLOOKUP(B1401,[1]Sheet1!$B:$B,[1]Sheet1!$R:$R,0) -> 0 | P1401: =_xlfn.XLOOKUP(B1401,[1]Sheet1!$B:$B,[1]Sheet1!$S:$S,0) -> 0 | Q1401: =_xlfn.XLOOKUP(B1401,[1]Sheet1!$B:$B,[1]Sheet1!$T:$T,0) -> 0 | R1401: =_xlfn.XLOOKUP(B1401,[1]Sheet1!$B:$B,[1]Sheet1!$U:$U,0) -> 0 | S1401: =_xlfn.XLOOKUP(B1401,[1]Sheet1!$B:$B,[1]Sheet1!$V:$V,0) -> 0 | T1401: =_xlfn.XLOOKUP(B1401,[1]Sheet1!$B:$B,[1]Sheet1!$W:$W,0) -> 0 | U1401: =_xlfn.XLOOKUP(B1401,[1]Sheet1!$B:$B,[1]Sheet1!$X:$X,0) -> 0 | V1401: =_xlfn.XLOOKUP(B1401,[1]Sheet1!$B:$B,[1]Sheet1!$Y:$Y,0) -> 0 | W1401: =SUM(K1401:V1401) -> 0 | X1401: 451.070102.4514120.1.424521.4510700.200104.000.000000.000000 | Y1401: Museum Shared Services | Z1401: Museums - Finance | AA1401: 424521 - Manpower supply Other Than IT Related | AB1401: 200104 - FA104-Opex Expense | AC1401: Chapter 2 | AD1401: 070102 - Finance | AE1401: Museum Shared Services | AF1401: MSS OPEX Project Type | AG1401: 240000 | AH1401: =_xlfn.XLOOKUP(B1401,[1]Sheet1!$B:$B,[1]Sheet1!$AB:$AB,0) -> 0
B1402: =C1402&D1402&F1402&G1402&H1402 -> 451412045170000054510750424521200104 | C1402: 4514120 | D1402: 4517000005 | E1402: Museums - Receivables Operations | F1402: 4510750 | G1402: 424521 | H1402: 200104 | I1402: 424521 - Manpower supply Other Than IT Related | J1402: APPROVED | K1402: =_xlfn.XLOOKUP(B1402,[1]Sheet1!$B:$B,[1]Sheet1!$N:$N,0) -> 0 | L1402: =_xlfn.XLOOKUP(B1402,[1]Sheet1!$B:$B,[1]Sheet1!$O:$O,0) -> 0 | M1402: =_xlfn.XLOOKUP(B1402,[1]Sheet1!$B:$B,[1]Sheet1!$P:$P,0) -> 0 | N1402: =_xlfn.XLOOKUP(B1402,[1]Sheet1!$B:$B,[1]Sheet1!$Q:$Q,0) -> 0 | O1402: =_xlfn.XLOOKUP(B1402,[1]Sheet1!$B:$B,[1]Sheet1!$R:$R,0) -> 0 | P1402: =_xlfn.XLOOKUP(B1402,[1]Sheet1!$B:$B,[1]Sheet1!$S:$S,0) -> 0 | Q1402: =_xlfn.XLOOKUP(B1402,[1]Sheet1!$B:$B,[1]Sheet1!$T:$T,0) -> 0 | R1402: =_xlfn.XLOOKUP(B1402,[1]Sheet1!$B:$B,[1]Sheet1!$U:$U,0) -> 0 | S1402: =_xlfn.XLOOKUP(B1402,[1]Sheet1!$B:$B,[1]Sheet1!$V:$V,0) -> 0 | T1402: =_xlfn.XLOOKUP(B1402,[1]Sheet1!$B:$B,[1]Sheet1!$W:$W,0) -> 0 | U1402: =_xlfn.XLOOKUP(B1402,[1]Sheet1!$B:$B,[1]Sheet1!$X:$X,0) -> 0 | V1402: =_xlfn.XLOOKUP(B1402,[1]Sheet1!$B:$B,[1]Sheet1!$Y:$Y,0) -> 0 | W1402: =SUM(K1402:V1402) -> 0 | X1402: 451.070103.4514120.1.424521.4510700.200104.000.000000.000000 | Y1402: Museum Shared Services | Z1402: Museums - Finance | AA1402: 424521 - Manpower supply Other Than IT Related | AB1402: 200104 - FA104-Opex Expense | AC1402: Chapter 2 | AD1402: 070103 - Human Resource (HR) | AE1402: Museum Shared Services | AF1402: MSS OPEX Project Type | AG1402: 316206 | AH1402: =_xlfn.XLOOKUP(B1402,[1]Sheet1!$B:$B,[1]Sheet1!$AB:$AB,0) -> 0
B1403: =C1403&D1403&F1403&G1403&H1403 -> 451414045170000074510723424521200104 | C1403: 4514140 | D1403: 4517000007 | E1403: Museums - Talent Development | F1403: 4510723 | G1403: 424521 | H1403: 200104 | I1403: 424521 - Manpower supply Other Than IT Related | J1403: APPROVED | K1403: =_xlfn.XLOOKUP(B1403,[1]Sheet1!$B:$B,[1]Sheet1!$N:$N,0) -> 0 | L1403: =_xlfn.XLOOKUP(B1403,[1]Sheet1!$B:$B,[1]Sheet1!$O:$O,0) -> 0 | M1403: =_xlfn.XLOOKUP(B1403,[1]Sheet1!$B:$B,[1]Sheet1!$P:$P,0) -> 0 | N1403: =_xlfn.XLOOKUP(B1403,[1]Sheet1!$B:$B,[1]Sheet1!$Q:$Q,0) -> 0 | O1403: =_xlfn.XLOOKUP(B1403,[1]Sheet1!$B:$B,[1]Sheet1!$R:$R,0) -> 0 | P1403: =_xlfn.XLOOKUP(B1403,[1]Sheet1!$B:$B,[1]Sheet1!$S:$S,0) -> 0 | Q1403: =_xlfn.XLOOKUP(B1403,[1]Sheet1!$B:$B,[1]Sheet1!$T:$T,0) -> 0 | R1403: =_xlfn.XLOOKUP(B1403,[1]Sheet1!$B:$B,[1]Sheet1!$U:$U,0) -> 0 | S1403: =_xlfn.XLOOKUP(B1403,[1]Sheet1!$B:$B,[1]Sheet1!$V:$V,0) -> 0 | T1403: =_xlfn.XLOOKUP(B1403,[1]Sheet1!$B:$B,[1]Sheet1!$W:$W,0) -> 0 | U1403: =_xlfn.XLOOKUP(B1403,[1]Sheet1!$B:$B,[1]Sheet1!$X:$X,0) -> 0 | V1403: =_xlfn.XLOOKUP(B1403,[1]Sheet1!$B:$B,[1]Sheet1!$Y:$Y,0) -> 0 | W1403: =SUM(K1403:V1403) -> 0 | X1403: 451.070103.4514140.1.424521.4510700.200104.000.000000.000000 | Y1403: Museum Shared Services | Z1403: Museums - People and Performance | AA1403: 424521 - Manpower supply Other Than IT Related | AB1403: 200104 - FA104-Opex Expense | AC1403: Chapter 2 | AD1403: 070103 - Human Resource (HR) | AE1403: Museum Shared Services | AF1403: MSS OPEX Project Type | AG1403: 582444 | AH1403: =_xlfn.XLOOKUP(B1403,[1]Sheet1!$B:$B,[1]Sheet1!$AB:$AB,0) -> 0
B1404: =C1404&D1404&F1404&G1404&H1404 -> 451414045170000074510802413710100103 | C1404: 4514140 | D1404: 4517000007 | E1404: Museums - Talent Development | F1404: 4510802 | G1404: 413710 | H1404: 100103 | I1404: 413710 - Tuition fees Non IT Related | J1404: APPROVED | K1404: =_xlfn.XLOOKUP(B1404,[1]Sheet1!$B:$B,[1]Sheet1!$N:$N,0) -> 0 | L1404: =_xlfn.XLOOKUP(B1404,[1]Sheet1!$B:$B,[1]Sheet1!$O:$O,0) -> 0 | M1404: =_xlfn.XLOOKUP(B1404,[1]Sheet1!$B:$B,[1]Sheet1!$P:$P,0) -> 0 | N1404: =_xlfn.XLOOKUP(B1404,[1]Sheet1!$B:$B,[1]Sheet1!$Q:$Q,0) -> 0 | O1404: =_xlfn.XLOOKUP(B1404,[1]Sheet1!$B:$B,[1]Sheet1!$R:$R,0) -> 0 | P1404: =_xlfn.XLOOKUP(B1404,[1]Sheet1!$B:$B,[1]Sheet1!$S:$S,0) -> 0 | Q1404: =_xlfn.XLOOKUP(B1404,[1]Sheet1!$B:$B,[1]Sheet1!$T:$T,0) -> 0 | R1404: =_xlfn.XLOOKUP(B1404,[1]Sheet1!$B:$B,[1]Sheet1!$U:$U,0) -> 0 | S1404: =_xlfn.XLOOKUP(B1404,[1]Sheet1!$B:$B,[1]Sheet1!$V:$V,0) -> 0 | T1404: =_xlfn.XLOOKUP(B1404,[1]Sheet1!$B:$B,[1]Sheet1!$W:$W,0) -> 0 | U1404: =_xlfn.XLOOKUP(B1404,[1]Sheet1!$B:$B,[1]Sheet1!$X:$X,0) -> 0 | V1404: =_xlfn.XLOOKUP(B1404,[1]Sheet1!$B:$B,[1]Sheet1!$Y:$Y,0) -> 0 | W1404: =SUM(K1404:V1404) -> 0 | X1404: 451.070103.4514140.1.413710.4510700.100103.000.000000.000000 | Y1404: Museum Shared Services | Z1404: Museums - People and Performance | AA1404: 413710 - Tuition fees "Other Than IT Related" | AB1404: 100103 - FA103-Manpower Expense | AC1404: Chapter 1 | AD1404: 070103 - Human Resource (HR) | AE1404: Museum Shared Services | AF1404: MSS OPEX Project Type | AG1404: 2130000 | AH1404: =_xlfn.XLOOKUP(B1404,[1]Sheet1!$B:$B,[1]Sheet1!$AB:$AB,0) -> 0
B1405: =C1405&D1405&F1405&G1405&H1405 -> 451414045170000084510723424521200104 | C1405: 4514140 | D1405: 4517000008 | E1405: Museums - P&P Operations | F1405: 4510723 | G1405: 424521 | H1405: 200104 | I1405: 424521 - Manpower supply Other Than IT Related | J1405: APPROVED | K1405: =_xlfn.XLOOKUP(B1405,[1]Sheet1!$B:$B,[1]Sheet1!$N:$N,0) -> 0 | L1405: =_xlfn.XLOOKUP(B1405,[1]Sheet1!$B:$B,[1]Sheet1!$O:$O,0) -> 0 | M1405: =_xlfn.XLOOKUP(B1405,[1]Sheet1!$B:$B,[1]Sheet1!$P:$P,0) -> 0 | N1405: =_xlfn.XLOOKUP(B1405,[1]Sheet1!$B:$B,[1]Sheet1!$Q:$Q,0) -> 0 | O1405: =_xlfn.XLOOKUP(B1405,[1]Sheet1!$B:$B,[1]Sheet1!$R:$R,0) -> 0 | P1405: =_xlfn.XLOOKUP(B1405,[1]Sheet1!$B:$B,[1]Sheet1!$S:$S,0) -> 0 | Q1405: =_xlfn.XLOOKUP(B1405,[1]Sheet1!$B:$B,[1]Sheet1!$T:$T,0) -> 0 | R1405: =_xlfn.XLOOKUP(B1405,[1]Sheet1!$B:$B,[1]Sheet1!$U:$U,0) -> 0 | S1405: =_xlfn.XLOOKUP(B1405,[1]Sheet1!$B:$B,[1]Sheet1!$V:$V,0) -> 0 | T1405: =_xlfn.XLOOKUP(B1405,[1]Sheet1!$B:$B,[1]Sheet1!$W:$W,0) -> 0 | U1405: =_xlfn.XLOOKUP(B1405,[1]Sheet1!$B:$B,[1]Sheet1!$X:$X,0) -> 0 | V1405: =_xlfn.XLOOKUP(B1405,[1]Sheet1!$B:$B,[1]Sheet1!$Y:$Y,0) -> 0 | W1405: =SUM(K1405:V1405) -> 0 | X1405: 451.070103.4514140.1.424521.4510700.200104.000.000000.000000 | Y1405: Museum Shared Services | Z1405: Museums - People and Performance | AA1405: 424521 - Manpower supply Other Than IT Related | AB1405: 200104 - FA104-Opex Expense | AC1405: Chapter 2 | AD1405: 070103 - Human Resource (HR) | AE1405: Museum Shared Services | AF1405: MSS OPEX Project Type | AG1405: 1084569 | AH1405: =_xlfn.XLOOKUP(B1405,[1]Sheet1!$B:$B,[1]Sheet1!$AB:$AB,0) -> 0
B1406: =C1406&D1406&F1406&G1406&H1406 -> 451418045170000084510725424231200104 | C1406: 4514180 | D1406: 4517000008 | E1406: Museums - P&P Operations | F1406: 4510725 | G1406: 424231 | H1406: 200104 | I1406: 424231 - Events - Awards, prizes and gifts | J1406: APPROVED | K1406: =_xlfn.XLOOKUP(B1406,[1]Sheet1!$B:$B,[1]Sheet1!$N:$N,0) -> 0 | L1406: =_xlfn.XLOOKUP(B1406,[1]Sheet1!$B:$B,[1]Sheet1!$O:$O,0) -> 0 | M1406: =_xlfn.XLOOKUP(B1406,[1]Sheet1!$B:$B,[1]Sheet1!$P:$P,0) -> 0 | N1406: =_xlfn.XLOOKUP(B1406,[1]Sheet1!$B:$B,[1]Sheet1!$Q:$Q,0) -> 0 | O1406: =_xlfn.XLOOKUP(B1406,[1]Sheet1!$B:$B,[1]Sheet1!$R:$R,0) -> 0 | P1406: =_xlfn.XLOOKUP(B1406,[1]Sheet1!$B:$B,[1]Sheet1!$S:$S,0) -> 0 | Q1406: =_xlfn.XLOOKUP(B1406,[1]Sheet1!$B:$B,[1]Sheet1!$T:$T,0) -> 0 | R1406: =_xlfn.XLOOKUP(B1406,[1]Sheet1!$B:$B,[1]Sheet1!$U:$U,0) -> 0 | S1406: =_xlfn.XLOOKUP(B1406,[1]Sheet1!$B:$B,[1]Sheet1!$V:$V,0) -> 0 | T1406: =_xlfn.XLOOKUP(B1406,[1]Sheet1!$B:$B,[1]Sheet1!$W:$W,0) -> 0 | U1406: =_xlfn.XLOOKUP(B1406,[1]Sheet1!$B:$B,[1]Sheet1!$X:$X,0) -> 0 | V1406: =_xlfn.XLOOKUP(B1406,[1]Sheet1!$B:$B,[1]Sheet1!$Y:$Y,0) -> 0 | W1406: =SUM(K1406:V1406) -> 0 | X1406: 451.070103.4514180.1.424231.4510700.200104.000.000000.000000 | Y1406: Museum Shared Services | Z1406: Museums - People and Performance | AA1406: 424231 - Events - Awards, prizes & gifts | AB1406: 200104 - FA104-Opex Expense | AC1406: Chapter 2 | AD1406: 070103 - Human Resource (HR) | AE1406: Museum Shared Services | AF1406: MSS OPEX Project Type | AG1406: 1840450 | AH1406: =_xlfn.XLOOKUP(B1406,[1]Sheet1!$B:$B,[1]Sheet1!$AB:$AB,0) -> 0
... B1741: =C1741&D1741&F1741&G1741&H1741 -> 451400045170001104510820491811300105 | C1741: 4514000 | D1741: 4517000110 | E1741: Museum's Operations | F1741: 4510820 | G1741: 491811 | H1741: 300105 | I1741: 491811 - Heritage culture assts | J1741: APPROVED | K1741: =_xlfn.XLOOKUP(B1741,[1]Sheet1!$B:$B,[1]Sheet1!$N:$N,0) -> 0 | L1741: =_xlfn.XLOOKUP(B1741,[1]Sheet1!$B:$B,[1]Sheet1!$O:$O,0) -> 0 | M1741: =_xlfn.XLOOKUP(B1741,[1]Sheet1!$B:$B,[1]Sheet1!$P:$P,0) -> 0 | N1741: =_xlfn.XLOOKUP(B1741,[1]Sheet1!$B:$B,[1]Sheet1!$Q:$Q,0) -> 0 | O1741: =_xlfn.XLOOKUP(B1741,[1]Sheet1!$B:$B,[1]Sheet1!$R:$R,0) -> 0 | P1741: =_xlfn.XLOOKUP(B1741,[1]Sheet1!$B:$B,[1]Sheet1!$S:$S,0) -> 0 | Q1741: =_xlfn.XLOOKUP(B1741,[1]Sheet1!$B:$B,[1]Sheet1!$T:$T,0) -> 0 | R1741: =_xlfn.XLOOKUP(B1741,[1]Sheet1!$B:$B,[1]Sheet1!$U:$U,0) -> 0 | S1741: =_xlfn.XLOOKUP(B1741,[1]Sheet1!$B:$B,[1]Sheet1!$V:$V,0) -> 0 | T1741: =_xlfn.XLOOKUP(B1741,[1]Sheet1!$B:$B,[1]Sheet1!$W:$W,0) -> 0 | U1741: =_xlfn.XLOOKUP(B1741,[1]Sheet1!$B:$B,[1]Sheet1!$X:$X,0) -> 0 | V1741: =_xlfn.XLOOKUP(B1741,[1]Sheet1!$B:$B,[1]Sheet1!$Y:$Y,0) -> 0 | W1741: =SUM(K1741:V1741) -> 0 | X1741: 451.070402.4514000.1.491811.4510700.300105.000.000000.000000 | Y1741: Museum Shared Services | Z1741: Museums - Director’s Office | AA1741: 491811 - Heritage and cultural assets - Capital Expenditure | AB1741: 300105 - FA105-Capex Expense | AC1741: Chapter 3 | AD1741: 070402 - Museums development | AE1741: Museum Shared Services | AF1741: MSS OPEX Project Type | AG1741: 1317223 | AH1741: =_xlfn.XLOOKUP(B1741,[1]Sheet1!$B:$B,[1]Sheet1!$AB:$AB,0) -> 0

Sheet How to use
A1: The template is pre-filled with every project / task / expenditure type of the selected budget year, its full 10-segment GL combination and any cashflow amounts already saved — type the monthly amounts and upload the same file back.
A3: Budget year: 2026 | budget lines: 1739
A4: Keys (must not be edited): PROJECT, TASK, EXPENDITURE_TYPE.
A5: CF_TYPE = APPROVED or REVISED — copy a row and switch it to plan both.
A6: One column per accounting period (MM-YYYY): type the amount in the month cell.
A7: Blank month cells are ignored on upload; a typed 0 clears a saved amount.
A8: Columns after the months (GL_COMBINATION, SECTOR, ...) are reference only.

Sheet Details
