Workbook

Sheet Director & ED
B1: Sector | C1: Department-P&P | D1: Cost center | E1: PBP Emp. Name | F1: Email | G1: FBP Emp Name | H1: Email | I1: Department Name-ADERP | J1: FBP -UH | K1: Director/ ED Emp Name | L1: Key Users Names | M1: Key Users Email ID | N1: CC status
B2: Abu Dhabi Arabic Language Centre | C2: Central (Chairman & ED Offices) | D2: 4510195 | E2: Nader Sarieddine | F2: nsarieddine@dctabudhabi.ae | G2: Yasmeen Zuhair Masoud | H2: ymasoud@dctabudhabi.ae | I2: DCT - Arabic Language Central | J2: Mohannad Al Zubaidi | K2: Saeed H. Al Tunaiji | L2: Iman Saigal, soraya | M2: SFarag@alc.ae | N2: Active
B3: Abu Dhabi Arabic Language Centre | C3: Marketing & Communications Department | D3: 4519196 | E3: Nader Sarieddine | F3: nsarieddine@dctabudhabi.ae | G3: Yasmeen Zuhair Masoud | H3: ymasoud@dctabudhabi.ae | I3: Marketing & Communications Department | J3: Mohannad Al Zubaidi | K3: Dr.Yasser Mohammed Zamzam | L3: Malek Mohammad Abu Ageel, Hanya Alkhadra, Alicia Avila Al Mutawa, Asma Abdulla Alfalasi | M3: MAgeel@alc.ae, HAlkhadra@alc.ae, AMutawa@alc.ae, AFalasi@alc.ae | N3: NOT Active
B4: Abu Dhabi Arabic Language Centre | C4: Arabic Language Education & Research Department | D4: 4519197 | E4: Nader Sarieddine | F4: nsarieddine@dctabudhabi.ae | G4: Yasmeen Zuhair Masoud | H4: ymasoud@dctabudhabi.ae | I4: Arabic Language Education & Research Department | J4: Mohannad Al Zubaidi | K4: Khalil Alshaikh | L4: Razan Hussein, Mohamed Ghazal | M4: RaHussein@alc.ae, MGhazal@alc.ae | N4: NOT Active
B5: Abu Dhabi Arabic Language Centre | C5: Creative Content Department | D5: 4519199 | E5: Nader Sarieddine | F5: nsarieddine@dctabudhabi.ae | G5: Yasmeen Zuhair Masoud | H5: ymasoud@dctabudhabi.ae | I5: Creative Content Department | J5: Mohannad Al Zubaidi | K5: Nour Diar Bakerli | L5: Muataz Mahmoud Eweidat | M5: muataz.eweidat@alc.ae | N5: NOT Active
B6: Abu Dhabi Arabic Language Centre | C6: Literature Awards Department | D6: 4519200 | E6: Nader Sarieddine | F6: nsarieddine@dctabudhabi.ae | G6: Yasmeen Zuhair Masoud | H6: ymasoud@dctabudhabi.ae | I6: Literature Awards Department | J6: Mohannad Al Zubaidi | K6: Abdulrahman Mohamed Alnaqbi | L6: Irum Fawad Siddiqui, Rahmah Hasan Al-Abidi | M6: irum.siddiqui@alc.ae, RAbidi@alc.ae | N6: NOT Active
B7: Abu Dhabi Arabic Language Centre | C7: Specialized Library Department | D7: 4519201 | E7: Nader Sarieddine | F7: nsarieddine@dctabudhabi.ae | G7: Yasmeen Zuhair Masoud | H7: ymasoud@dctabudhabi.ae | I7: Specialized Library Department | J7: Mohannad Al Zubaidi | K7: Juma Mohammed Ali Al Dhaheri | L7: Sara Mohamed Al Saadi | M7: SSaadi@alc.ae | N7: NOT Active
B8: Abu Dhabi Arabic Language Centre | C8: Strategic Planning Office | D8: 4519202 | E8: Nader Sarieddine | F8: nsarieddine@dctabudhabi.ae | G8: Yasmeen Zuhair Masoud | H8: ymasoud@dctabudhabi.ae | I8: Strategic Planning Office | J8: Mohannad Al Zubaidi | K8: Karin Aghadjanian | L8: Andrawes Snobar | M8: ASnobar@alc.ae | N8: NOT Active
B9: Abu Dhabi Arabic Language Centre | C9: Bookfairs & Events Department | D9: 4519203 | E9: Nader Sarieddine | F9: nsarieddine@dctabudhabi.ae | G9: Yasmeen Zuhair Masoud | H9: ymasoud@dctabudhabi.ae | I9: Bookfairs & Events Department | J9: Mohannad Al Zubaidi | K9: Ayesha Eid AlMazrouei | L9: Ammar Ajlouni | M9: AAjlouni@alc.ae | N9: NOT Active
B10: AD Gaming & Digital | C10: AD Gaming & Digital Development | D10: 4518113 | E10: Hossam El Derbi | F10: hderbi@dctabudhabi.ae | G10: Mohannad Al Zubaidi | H10: mzubaidi@dctabudhabi.ae | I10: ED Gaming | J10: Mohannad Al Zubaidi | K10: Aziza Al Ahmadi | L10: Marcos Muller , Renato Franchi ,Ban Kattan | M10: MMuller@dctabudhabi.ae,RFranchi@dctabudhabi.ae,BKattan@dctabudhabi.ae | N10: Active
B11: Culture | C11: Historic Environment | D11: 4511300 | E11: Waddah Zanah | F11: wzanah@dctabudhabi.ae | G11: Mohannad Al Zubaidi | H11: mzubaidi@dctabudhabi.ae | I11: DCT - Historical Environment Dept | J11: Mohannad Al Zubaidi | K11: Jaber Saleh Al Merri | L11: Mohammed Al Harmoodi ,Shaikha Al Nasri | M11: m.alharmoodi@dctabudhabi.ae/snasri@dctabudhabi.ae | N11: Active
B12: Culture | C12: Intangible Cultural Heritage | D12: 4511600 | E12: Waddah Zanah | F12: wzanah@dctabudhabi.ae | G12: Mohannad Al Zubaidi | H12: mzubaidi@dctabudhabi.ae | I12: DCT - Intangible Heritage Dept | J12: Mohannad Al Zubaidi | K12: Saeed Hamad Ali Al Kaabi | L12: Maha Salah Eddin Kilani | M12: maha.kilani@dctabudhabi.ae | N12: Active
B13: Culture | C13: Library Management | D13: 4516100 | E13: Waddah Zanah | F13: wzanah@dctabudhabi.ae | G13: Mohannad Al Zubaidi | H13: mzubaidi@dctabudhabi.ae | I13: DCT - library | J13: Mohannad Al Zubaidi | K13: Fatema Abdul Rahman Al Tamimi | L13: Jasim Mohamed Al Awadi | M13: JAwadi@dctabudhabi.ae | N13: Active
... B21: Culture | C21: Education & Outreach | D21: 4511800 | E21: Omer Khan | F21: okhan@dctabudhabi.ae | G21: Noora Al Bader | H21: nalbadrsharif@dctabudhabi.ae | I21: Education & Outreach | J21: Mohannad Al Zubaidi | K21: Ranya Camille Nasser | L21: Rand Abdul Jabbar , James Matthews , Lubna Ali Abdulla Al Teneiji | M21: JMatthews@dctabudhabi.ae ,LTeneiji@dctabudhabi.ae,RAbdulJabbar@dctabudhabi.ae | N21: Active
B22: Office of Undersecretary | C22: Office Of Undersecretary | D22: 4510110 | E22: Hossam El Derbi | F22: hderbi@dctabudhabi.ae | G22: Yasmeen Zuhair Masoud | H22: ymasoud@dctabudhabi.ae | I22: DCT - Executive Management Office | J22: Mohannad Al Zubaidi | K22: Saood Abdulaziz Mohamed Alhosa | N22: Active
B23: Office of Undersecretary | C23: Internal Audit Office | D23: 4510140 | E23: Hossam El Derbi | F23: hderbi@dctabudhabi.ae | G23: Yasmeen Zuhair Masoud | H23: ymasoud@dctabudhabi.ae | I23: Internal Audit | J23: Mohannad Al Zubaidi | K23: Wissam Halimi | L23: Ashraf Amro | M23: AAmro@dctabudhabi.ae | N23: Active
B24: Office of Undersecretary | C24: Project Management & Engineering | D24: 4510150 | E24: Hossam El Derbi | F24: hderbi@dctabudhabi.ae | G24: Yasmeen Zuhair Masoud | H24: ymasoud@dctabudhabi.ae | I24: Project Management & Engineering | J24: Mohannad Al Zubaidi | K24: Said Ali Al-Khatib | L24: Noha Moussa | M24: Noha.Moussa@dctabudhabi.ae | N24: Active
B25: Office of Undersecretary | C25: Tendering & Projects Control | D25: 4510155 | E25: Hossam El Derbi | F25: hderbi@dctabudhabi.ae | G25: Yasmeen Zuhair Masoud | H25: ymasoud@dctabudhabi.ae | I25: Tendering & Projects Control | J25: Mohannad Al Zubaidi | K25: Khader bu Abu Ghannam | L25: Michella Moussi | M25: MMoussi@dctabudhabi.ae | N25: Active
B26: Office of Undersecretary | C26: Legal & Government Affairs | D26: 4510160 | E26: Hossam El Derbi | F26: hderbi@dctabudhabi.ae | G26: Yasmeen Zuhair Masoud | H26: ymasoud@dctabudhabi.ae | I26: Legal & Government Affairs | J26: Mohannad Al Zubaidi | K26: Mohammed Ahmed Frehat | L26: Halima Kourrate | M26: HKourrate@dctabudhabi.ae | N26: Active
B27: Office of Undersecretary | C27: Executive Affairs | D27: 4510011 | E27: Hossam El Derbi | F27: hderbi@dctabudhabi.ae | G27: Yasmeen Zuhair Masoud | H27: ymasoud@dctabudhabi.ae | I27: Executive Affairs | J27: Mohannad Al Zubaidi | N27: NOT Active
B28: Strategic Affairs | C28: Office of the Strategic Affairs Executive Director | D28: 4512010 | E28: Hossam El Derbi | F28: hderbi@dctabudhabi.ae | G28: Anwar AL Mussaibi | H28: asalmessabi@dctabudhabi.ae | I28: DCT - Office of the Strategic Affairs Executive Director | J28: Mohamed Elgayar | K28: Saeed Al Fazari | L28: Hanaa AbuShawish Hanzada Abdalaziz | M28: Hanaa AbuShawish <HShawish@dctabudhabi.ae> Hanzada Abdalaziz <HAbdalaziz@dctabudhabi.ae> | N28: Active
B29: Strategic Affairs | C29: Strategy Planning | D29: 4512100 | E29: Hossam El Derbi | F29: hderbi@dctabudhabi.ae | G29: Anwar AL Mussaibi | H29: asalmessabi@dctabudhabi.ae | I29: DCT - Strategy Planning | J29: Mohamed Elgayar | K29: Wail Kayali | L29: Hanaa AbuShawish Hanzada Abdalaziz | M29: Hanaa AbuShawish <HShawish@dctabudhabi.ae> Hanzada Abdalaziz <HAbdalaziz@dctabudhabi.ae> | N29: Active
B30: Strategic Affairs | C30: Business Intelligence | D30: 4512200 | E30: Hossam El Derbi | F30: hderbi@dctabudhabi.ae | G30: Anwar AL Mussaibi | H30: asalmessabi@dctabudhabi.ae | I30: DCT - Business Intelligence | J30: Mohamed Elgayar | K30: David Millan | L30: Hanaa AbuShawish Hanzada Abdalaziz | M30: Hanaa AbuShawish <HShawish@dctabudhabi.ae> Hanzada Abdalaziz <HAbdalaziz@dctabudhabi.ae> | N30: Active
B31: Strategic Affairs | C31: Business Excellence and Continuity | D31: 4512300 | E31: Hossam El Derbi | F31: hderbi@dctabudhabi.ae | G31: Anwar AL Mussaibi | H31: asalmessabi@dctabudhabi.ae | I31: DCT - Business Exellence & Continuity | J31: Mohamed Elgayar | K31: Abdulla Naeser Al Blooshi | L31: Hanaa AbuShawish Hanzada Abdalaziz | M31: Hanaa AbuShawish <HShawish@dctabudhabi.ae> Hanzada Abdalaziz <HAbdalaziz@dctabudhabi.ae> | N31: Active
B32: Strategic Marketing & Communication | C32: Creative & Production | D32: 4513110 | E32: Wasim Haider Ali | F32: wali@dctabudhabi.ae | G32: Said Drissi | H32: sdrissi@dctabudhabi.ae | I32: DCT - Creative and Production Department | J32: Mohamed Elgayar | K32: Ghadeer Khub | L32: Emad Haj Abdul Fattah & Mohammed Abdelwahed | M32: EFattah@dctabudhabi.ae / MAbdelwahed@dctabudhabi.ae | N32: Active
B33: Strategic Marketing & Communication | C33: Strategic Communications | D33: 4513120 | E33: Wasim Haider Ali | F33: wali@dctabudhabi.ae | G33: Said Drissi | H33: sdrissi@dctabudhabi.ae | I33: Strategic Communications | J33: Mohamed Elgayar | K33: Jacqueline Jain | L33: Emad Haj Abdul Fattah & Mohammed Abdelwahed | M33: EFattah@dctabudhabi.ae / MAbdelwahed@dctabudhabi.ae | N33: Active
B34: Strategic Marketing & Communication | C34: Planning, Strategy & Operations | D34: 4513130 | E34: Wasim Haider Ali | F34: wali@dctabudhabi.ae | G34: Said Drissi | H34: sdrissi@dctabudhabi.ae | I34: DCT - Planning, Strategy & Operations Department | J34: Mohamed Elgayar | K34: Georgios Kalliamvakos | L34: Emad Haj Abdul Fattah & Mohammed Abdelwahed | M34: EFattah@dctabudhabi.ae / MAbdelwahed@dctabudhabi.ae | N34: Active
B35: Strategic Marketing & Communication | C35: Sector Marketing | D35: 4513140 | E35: Wasim Haider Ali | F35: wali@dctabudhabi.ae | G35: Said Drissi | H35: sdrissi@dctabudhabi.ae | I35: Sector Marketing | J35: Mohamed Elgayar | K35: Emma campbell | L35: Emad Haj Abdul Fattah & Mohammed Abdelwahed | M35: EFattah@dctabudhabi.ae / MAbdelwahed@dctabudhabi.ae | N35: Active
B36: Strategic Marketing & Communication | C36: ED office | D36: 4513111 | E36: Wasim Haider Ali | F36: wali@dctabudhabi.ae | G36: Said Drissi | H36: sdrissi@dctabudhabi.ae | I36: ED office | J36: Mohamed Elgayar | K36: Nouf AlBoushelaibi | N36: NOT Active
B37: Support Services | C37: Office of the Executive Director, Support Services | D37: 4510201 | E37: Nader Sarieddine | F37: nsarieddine@dctabudhabi.ae | G37: Anwar AL Mussaibi | H37: asalmessabi@dctabudhabi.ae | I37: DCT - Support Services (Central) | J37: Mohamed Elgayar | K37: Hamad Mohammed Saeed Alsudain | L37: Maissa Ahmad Arke | M37: Maissa Ahmad Arke <MArke@dctabudhabi.ae> | N37: Active
B38: Support Services | C38: Finance | D38: 4510210 | E38: Nader Sarieddine | F38: nsarieddine@dctabudhabi.ae | G38: Anwar AL Mussaibi | H38: asalmessabi@dctabudhabi.ae | I38: DCT - Finance | J38: Mohamed Elgayar | K38: Rakan Sabbagh | L38: Maitha Mohammed Alblooshi | M38: MABlooshi@dctabudhabi.ae | N38: Active
B39: Support Services | C39: People & Performance | D39: 4510220 | E39: Nader Sarieddine | F39: nsarieddine@dctabudhabi.ae | G39: Anwar AL Mussaibi | H39: asalmessabi@dctabudhabi.ae | I39: DCT - People & Performance | J39: Mohamed Elgayar | K39: Ahmed Mohamed Alhosani | L39: Yassar Mehmood Khan | M39: ykhan@dctabudhabi.ae | N39: Active
B40: Support Services | C40: Supply Management | D40: 4510240 | E40: Nader Sarieddine | F40: nsarieddine@dctabudhabi.ae | G40: Anwar AL Mussaibi | H40: asalmessabi@dctabudhabi.ae | I40: DCT - Supply Management | J40: Mohamed Elgayar | K40: Khalifa Ahmed Almarzooqi | L40: Muhammad Mubeen | M40: Muhammad Mubeen <MMubeen@dctabudhabi.ae> | N40: Active
B41: Support Services | C41: Technology | D41: 4510250 | E41: Nader Sarieddine Mohammed Sherief | F41: nsarieddine@dctabudhabi.ae mssairaj@dctabudhabi.ae | G41: Anwar AL Mussaibi | H41: asalmessabi@dctabudhabi.ae | I41: DCT - Smart System & Government Services | J41: Mohamed Elgayar | K41: Abdel Ghani Amer | L41: Saji Asok | M41: sasok@dctabudhabi.ae | N41: Active
B42: Support Services | C42: Facilities Management & General Services | D42: 4510230 | E42: Mohammed Sherief | F42: mssairaj@dctabudhabi.ae | G42: Anwar AL Mussaibi | H42: asalmessabi@dctabudhabi.ae | I42: DCT - Facility & General Services Management | J42: Mohamed Elgayar | K42: Khalifa Ahmed Almarzooqi | L42: Omar Al Jawhari, Abdulrahman Baharoon | N42: NOT Active
B43: Tourism | C43: Licensing & Regulatory Compliance | D43: 4510170 | E43: Mohammed Sherief | F43: mssairaj@dctabudhabi.ae | G43: Belal Ghassan | H43: bghassan@dctabudhabi.ae | I43: DCT - Control & Licensing | J43: Mohamed Elgayar | K43: Sultan S. Al Awani | L43: Hana Rabba | M43: HYRabah@dctabudhabi.ae | N43: Active
B44: Tourism | C44: Visitors Experience | D44: 4515300 | E44: Mohammed Sherief Sairaj | F44: mssairaj@dctabudhabi.ae | G44: Belal Ghassan | H44: bghassan@dctabudhabi.ae | I44: DCT - Visitor Experience & Tourism Products Development | J44: Mohamed Elgayar | K44: Gihan El Matbouly | L44: Faheem Mohammed | M44: FUMohammed@dctabudhabi.ae | N44: Active
B45: Tourism | C45: Abu Dhabi Conventions & Exhibition Bureau | D45: 4515400 | E45: Fatema Mohsin al fardan | F45: falfardan@dctabudhabi.ae | G45: Belal Ghassan | H45: bghassan@dctabudhabi.ae | I45: DCT - Abu Dhabi Conventions & Exhibition Bureau | J45: Mohamed Elgayar | K45: Mubarak Hamad Al Shamisi | L45: Asanka Lankapurage / SaKumar@dctabudhabi.ae | M45: ALankapurage@dctabudhabi.ae / SaKumar@dctabudhabi.ae | N45: Active
B46: Tourism | C46: Abu Dhabi Events Bureau | D46: 4515500 | E46: Fatema Mohsin al fardan | F46: falfardan@dctabudhabi.ae | G46: Amruddin Shajahan | H46: ashajahan@dctabudhabi.ae | I46: DCT - Abu Dhabi Events Bureau | J46: Mohamed Elgayar | K46: Fakhry Maher Alsarraj | L46: Mohamed Rafiudeen Samsudeen | M46: msamsudeen@dctabudhabi.ae | N46: Active
B47: Tourism | C47: Al Ain & Al Dhafra Regional Development | D47: 4515700 | E47: Fatema Mohsin al fardan | F47: falfardan@dctabudhabi.ae | G47: Belal Ghassan | H47: bghassan@dctabudhabi.ae | I47: DCT - Al Ain & Al Dhafra Regional Development Department | J47: Mohamed Elgayar | K47: Saeed A. Al Dhaheri | L47: Zoran Ninic | M47: ZNinic@dctabudhabi.ae | N47: Active
...

Sheet Director & ED Jan 2026
A1: Old Sector | B1: Cost center | C1: Old Department Name-ADERP-as Per DOF | D1: New Cost center | E1: New Sector | F1: New Department Name-ADERP | G1: PBP Emp. Name | H1: Email | I1: FBP Emp Name | J1: Email | K1: FBP -UH | L1: Remarks | M1: AP Name | N1: AP Emails | O1: Director/ ED Emp Name | P1: Director /ED Email | Q1: Key Users Names | R1: Key Users Email ID | S1: CC status | T1: Action
A2: Abu Dhabi Arabic Language Centre | B2: 4510195 | C2: DCT - Arabic Language Central | D2: 4510195 | E2: Arabic Language Centre | F2: ALC - Arabic Language Centre (Central) | G2: Nader Khaled Sarieddine | H2: nsarieddine@dctabudhabi.ae | I2: Noora Al Bader | J2: nalbadrsharif@dctabudhabi.ae | K2: Abdulrahman Alyafei | M2: Ibrahim Al jeinbi | N2: ialjneibi@dctabudhabi.ae | O2: Saeed H. Al Tunaiji | P2: stanaiji@alc.ae | Q2: Iman Saigal, soraya,Walid Ahmed Alaaeldin | R2: SFarag@alc.ae waaeldin@alc.ae | S2: Active
A3: Abu Dhabi Arabic Language Centre | B3: 4519196 | C3: ALC- Marketing & Communications Department | D3: 4519196 | E3: Arabic Language Centre | F3: ALC- Marketing & Communications Department | G3: Nader Khaled Sarieddine | H3: nsarieddine@dctabudhabi.ae | I3: Noora Al Bader | J3: nalbadrsharif@dctabudhabi.ae | K3: Abdulrahman Alyafei | M3: Ibrahim Al jeinbi | N3: ialjneibi@dctabudhabi.ae | O3: Dr.Yasser Mohammed Zamzam | P3: yzamzam@alc.ae | Q3: Malek Mohammad Abu Ageel, Hanya Alkhadra, Alicia Avila Al Mutawa, Asma Abdulla Alfalasi | R3: MAgeel@alc.ae, HAlkhadra@alc.ae, AMutawa@alc.ae, AFalasi@alc.ae | S3: Active
A4: Abu Dhabi Arabic Language Centre | B4: 4519197 | C4: ALC- Arabic Language Education & Research Department | D4: 4519197 | E4: Arabic Language Centre | F4: ALC- Arabic Language Education & Research Department | G4: Nader Khaled Sarieddine | H4: nsarieddine@dctabudhabi.ae | I4: Noora Al Bader | J4: nalbadrsharif@dctabudhabi.ae | K4: Abdulrahman Alyafei | M4: Ibrahim Al jeinbi | N4: ialjneibi@dctabudhabi.ae | O4: Khalil Alshaikh | P4: kalshaikh@alc.ae | Q4: Razan Hussein, Mohamed Ghazal | R4: RaHussein@alc.ae, MGhazal@alc.ae | S4: Active
A5: Abu Dhabi Arabic Language Centre | B5: 4519199 | C5: ALC- Creative Content Department | D5: 4519199 | E5: Arabic Language Centre | F5: ALC- Creative Content Department | G5: Nader Khaled Sarieddine | H5: nsarieddine@dctabudhabi.ae | I5: Noora Al Bader | J5: nalbadrsharif@dctabudhabi.ae | K5: Abdulrahman Alyafei | M5: Ibrahim Al jeinbi | N5: ialjneibi@dctabudhabi.ae | O5: Nour Diar Bakerli | P5: ndiarbakerli@alc.ae | Q5: Muataz Mahmoud Eweidat | R5: muataz.eweidat@alc.ae | S5: Active
A6: Abu Dhabi Arabic Language Centre | B6: 4519200 | C6: ALC- Bookfairs & Events Department | D6: 4519200 | E6: Arabic Language Centre | F6: ALC- Bookfairs & Events Department | G6: Nader Khaled Sarieddine | H6: nsarieddine@dctabudhabi.ae | I6: Noora Al Bader | J6: nalbadrsharif@dctabudhabi.ae | K6: Abdulrahman Alyafei | M6: Ibrahim Al jeinbi | N6: ialjneibi@dctabudhabi.ae | O6: Ayesha Eid AlMazrouei | P6: amazrouei@alc.ae | Q6: Ammar Ajlouni | R6: AAjlouni@alc.ae | S6: Active
A7: Abu Dhabi Arabic Language Centre | B7: 4519201 | C7: ALC- Literature Awards Department | D7: 4519201 | E7: Arabic Language Centre | F7: ALC- Literature Awards Department | G7: Nader Khaled Sarieddine | H7: nsarieddine@dctabudhabi.ae | I7: Noora Al Bader | J7: nalbadrsharif@dctabudhabi.ae | K7: Abdulrahman Alyafei | M7: Ibrahim Al jeinbi | N7: ialjneibi@dctabudhabi.ae | O7: Abdulrahman Mohamed Alnaqbi | P7: alnaqbi@alc.ae | Q7: Irum Fawad Siddiqui, Rahmah Hasan Al-Abidi | R7: irum.siddiqui@alc.ae, RAbidi@alc.ae | S7: Active
A8: Abu Dhabi Arabic Language Centre | B8: 4519202 | C8: ALC- Specialized Library Department | D8: 4519202 | E8: Arabic Language Centre | F8: ALC- Specialized Library Department | G8: Nader Khaled Sarieddine | H8: nsarieddine@dctabudhabi.ae | I8: Noora Al Bader | J8: nalbadrsharif@dctabudhabi.ae | K8: Abdulrahman Alyafei | M8: Ibrahim Al jeinbi | N8: ialjneibi@dctabudhabi.ae | O8: Juma Mohammed Ali Al Dhaheri | P8: jdhaheri@alc.ae | Q8: Sara Mohamed Al Saadi | R8: SSaadi@alc.ae | S8: Active
A9: Abu Dhabi Arabic Language Centre | B9: 4519203 | C9: ALC- Strategic Planning Office | D9: 4519203 | E9: Arabic Language Centre | F9: ALC- Strategic Planning Office | G9: Nader Khaled Sarieddine | H9: nsarieddine@dctabudhabi.ae | I9: Noora Al Bader | J9: nalbadrsharif@dctabudhabi.ae | K9: Abdulrahman Alyafei | M9: Ibrahim Al jeinbi | N9: ialjneibi@dctabudhabi.ae | O9: Karin Aghadjanian | P9: karin.aghadjanian@alc.ae | Q9: Andrawes Snobar | R9: ASnobar@alc.ae | S9: Active
A10: Abu Dhabi Arabic Language Centre | B10: 4519204 | C10: ALC - Corporate Communication Office Head | D10: 4519204 | E10: Arabic Language Centre | F10: ALC - Corporate Communication Office Head | G10: Nader Khaled Sarieddine | H10: nsarieddine@dctabudhabi.ae | I10: Noora Al Bader | J10: nalbadrsharif@dctabudhabi.ae | K10: Abdulrahman Alyafei | O10: Walid Ahmed Alaaeldin | P10: waaeldin@alc.ae | Q10: Khawla Ibrahim Almarzooqi Hafsa Mohamed Saeed Hamoud Al BUSeedi | R10: kmarzooqi@alc.ae, hafsa.albusaeedi@alc.ae | S10: NOT Active
A11: Culture | B11: 4511300 | C11: DCT - Historical Environment Dept | D11: 4511300 | E11: Culture | F11: DCT - Historical Environment Dept | G11: Waddah Mohammad Zanah | H11: wzanah@dctabudhabi.ae | I11: Anwar AL Mussaibi | J11: asalmessabi@dctabudhabi.ae | K11: Abdulrahman Alyafei | M11: Mohamed Thabit/Ahmed Samaneh | N11: mthabet@dctabudhabi.ae/asamaneh@dctabudhabi.ae | O11: Jaber Saleh Al Merri | P11: Jaber.Almerri@dctabudhabi.ae | Q11: Hafsa Mohamed Saeed Hamoud Al BUSeedi | R11: m.alharmoodi@dctabudhabi.ae | S11: Active
A12: Culture | B12: 4511600 | C12: DCT - Intangible Heritage Dept | D12: 4511600 | E12: Culture | F12: DCT - Intangible Cultural Heritage Department | G12: Waddah Mohammad Zanah | H12: wzanah@dctabudhabi.ae | I12: Anwar AL Mussaibi | J12: asalmessabi@dctabudhabi.ae | K12: Abdulrahman Alyafei | M12: Mohamed Thabit/Ahmed Samaneh | N12: mthabet@dctabudhabi.ae/asamaneh@dctabudhabi.ae | O12: Farah Abdulhameed Al Bakoush | P12: FBakoush@dctabudhabi.ae | Q12: Maha Salah Aldeen Kilani | R12: maha.kilani@dctabudhabi.ae | S12: Active
A13: Culture | B13: 4516100 | C13: DCT - Library Dept | D13: 4516100 | E13: Culture | F13: DCT - Library Management Department | G13: Waddah Mohammad Zanah | H13: wzanah@dctabudhabi.ae | I13: Anwar AL Mussaibi | J13: asalmessabi@dctabudhabi.ae | K13: Abdulrahman Alyafei | M13: Mohamed Thabit/Ahmed Samaneh | N13: mthabet@dctabudhabi.ae/asamaneh@dctabudhabi.ae | O13: Fatema Abdul Rahman Al Tamimi | P13: fatema.altamimi@dctabudhabi.ae | Q13: Jasim Mohamed Al Awadi | R13: jawadi@dctabudhabi.ae | S13: Active
A14: Culture | B14: 4511010 | C14: DCT - Culture (Central) Dept | D14: 4511010 | E14: Culture | F14: DCT - Culture (Central) Dept | G14: Waddah Mohammad Zanah | H14: wzanah@dctabudhabi.ae | I14: Anwar AL Mussaibi | J14: asalmessabi@dctabudhabi.ae | K14: Abdulrahman Alyafei | M14: Mohamed Thabit/Ahmed Samaneh | N14: mthabet@dctabudhabi.ae/asamaneh@dctabudhabi.ae | O14: Rita Aoun | P14: RAoun@dctabudhabi.ae | Q14: Mehdi Rhaiem | R14: MRhaiem@dctabudhabi.ae | S14: Active
A15: Culture | B15: 4511011 | C15: DCT - Abu Dhabi Public Art | G15: Omer Khan Habib | H15: okhan@dctabudhabi.ae | I15: Anwar AL Mussaibi | J15: asalmessabi@dctabudhabi.ae | O15: Reem Ghaith Fadda | P15: RFadda@dctabudhabi.ae | Q15: Clemence Marie Bergal | R15: CBergal@dctabudhabi.ae | S15: NOT Active
A16: Culture | B16: 4511150 | C16: DCT - Culture Planning & Development Dept. | D16: 4511150 | E16: Culture | F16: DCT - Scientific, Curatorial and Collection Department | G16: Waddah Mohammad Zanah | H16: wzanah@dctabudhabi.ae | I16: Anwar AL Mussaibi | J16: asalmessabi@dctabudhabi.ae | K16: Abdulrahman Alyafei | M16: Mohamed Thabit/Ahmed Samaneh | N16: mthabet@dctabudhabi.ae/asamaneh@dctabudhabi.ae | O16: Mehdi Rhaiem | P16: MRhaiem@dctabudhabi.ae | Q16: Mehdi Rhaiem | R16: MRhaiem@dctabudhabi.ae | S16: Active
A17: Culture | B17: 4511250 | C17: DCT - Cultural Sites Dept | D17: 4511250 | E17: Culture | F17: DCT - Culture Sites Management Department | G17: Omer Khan Habib & Waddah Mohammad Zanah | H17: okhan@dctabudhabi.ae wzanah@dctabudhabi.ae | I17: Khaled Suhail Alhashmi | J17: kalhashmi@dctabudhabi.ae | K17: Abdulrahman Alyafei | M17: Mohamed Thabit/Ahmed Samaneh | N17: mthabet@dctabudhabi.ae/asamaneh@dctabudhabi.ae | O17: Salama Nasser Al Shamsi/Ahmed Ma'ath Humaid | P17: salshamsi@dctabudhabi.ae/amhumaid@dctabudhabi.ae | Q17: Esraa Mohamed Al Atayeb Yosra El Hassan Imaad Riaz | R17: EHashim@dctabudhabi.ae YElHassan@dctabudhabi.ae IRiaz@dctabudhabi.ae | S17: Active
A18: Culture | B18: 4511550 | C18: DCT - Marketing & Communication Dept. | D18: 4511550 | E18: Culture | F18: DCT - Culture Sector Marketing Department | G18: Omer Khan Habib | H18: okhan@dctabudhabi.ae | I18: Anwar AL Mussaibi | J18: asalmessabi@dctabudhabi.ae | K18: Abdulrahman Alyafei | M18: Mohamed Thabit/Ahmed Samaneh | N18: mthabet@dctabudhabi.ae/asamaneh@dctabudhabi.ae | O18: Sherine Noural Din AbdelGafar | P18: SAbdelGafar@dctabudhabi.ae | Q18: Ehab Hani Haddad | R18: EHaddad@dctabudhabi.ae | S18: Active
A19: Culture | B19: 4511700 | C19: DCT - Cultural Programs Dept | D19: 4511700 | E19: Culture | F19: DCT - Culture Programming Department | G19: Omer Khan Habib | H19: okhan@dctabudhabi.ae | I19: Anwar AL Mussaibi | J19: asalmessabi@dctabudhabi.ae | K19: Abdulrahman Alyafei | M19: Mohamed Thabit/Ahmed Samaneh | N19: mthabet@dctabudhabi.ae/asamaneh@dctabudhabi.ae | O19: Reem Ghaith Fadda | P19: RFadda@dctabudhabi.ae | Q19: Sarah Saadoun | R19: SSaadoun@dctabudhabi.ae | S19: Active
A20: Culture | B20: 4511750 | C20: DCT – Culture Festivals & Platforms Dept | D20: 4511750 | E20: Culture | F20: DCT – Culture Festivals & Platforms Dept | G20: Hanan Nezam Alasad | H20: halasad@dctabudhabi.ae | I20: Anwar AL Mussaibi | J20: asalmessabi@dctabudhabi.ae | K20: Abdulrahman Alyafei | M20: Mohamed Thabit/Ahmed Samaneh | N20: mthabet@dctabudhabi.ae/asamaneh@dctabudhabi.ae | O20: Farah Abdulhameed Al Bakoush | P20: FBakoush@dctabudhabi.ae | Q20: Jood Mohamed AlJneibi Rowdha Mohamed Alnaqeeb | R20: JAlJneibi@dctabudhabi.ae RAlnaqeeb@dctabudhabi.ae | S20: Active
A21: Culture | B21: 4511800 | C21: DCT - Education & Outreach Dept | D21: 4511800 | E21: Culture | F21: DCT - Education & Outreach Dept | G21: Hanan Nezam Alasad | H21: halasad@dctabudhabi.ae | I21: Anwar AL Mussaibi | J21: asalmessabi@dctabudhabi.ae | K21: Abdulrahman Alyafei | M21: Mohamed Thabit/Ahmed Samaneh | N21: mthabet@dctabudhabi.ae/asamaneh@dctabudhabi.ae | O21: Ranya Camille Nasser | P21: RNasser@dctabudhabi.ae | Q21: Rand Abdul Jabbar Lubna Ali Abdulla Al Teneiji Moza Humaid AlMazroua | R21: RAbdulJabbar@dctabudhabi.ae LTeneiji@dctabudhabi.ae MAlmazroua@dctabudhabi.ae | S21: Active
D22: 4511020 | E22: Culture | F22: DCT - Culture Sector Policy and Development Office | G22: Omer Khan Habib | H22: okhan@dctabudhabi.ae | I22: Anwar AL Mussaibi | J22: asalmessabi@dctabudhabi.ae | K22: Abdulrahman Alyafei | M22: Mohamed Thabit/Ahmed Samaneh | N22: mthabet@dctabudhabi.ae/asamaneh@dctabudhabi.ae | O22: Mehdi Rhaiem | P22: MRhaiem@dctabudhabi.ae | Q22: Mehdi Rhaiem | R22: MRhaiem@dctabudhabi.ae | S22: Active
A23: Office of Undersecretary | B23: 4510110 | C23: DCT - Executive Mngt Office | D23: 4510110 | E23: Executive Office | F23: DCT - Executive Management Office (Central) | G23: Hossam Bassem El-Derbi | H23: hderbi@dctabudhabi.ae | I23: Yasmeen Zuhair Masoud | J23: ymasoud@dctabudhabi.ae | K23: Abdulrahman Alyafei | M23: Hiba Hassan | N23: hsleiman@dctabudhabi.ae | O23: Saood Abdulaziz Mohamed Al Hosani | P23: SMAlHosani@dctabudhabi.ae | Q23: Fatima Hamad Al Midfa | R23: FHMidfa@dctabudhabi.ae | S23: Active
A24: Office of Undersecretary | B24: 4510140 | C24: DCT - Internal Audit Dept | D24: 4510140 | E24: Executive Office | F24: DCT - Internal Audit Office | G24: Hossam Bassem El-Derbi | H24: hderbi@dctabudhabi.ae | I24: Marawan Mostafa Gadalla | J24: mgadalla@dctabudhabi.ae | K24: Mohamed Elgayar | M24: Hiba Hassan | N24: hsleiman@dctabudhabi.ae | O24: Ashraf Amro | P24: AAmro@dctabudhabi.ae | Q24: Hassan Wael Barghouthi | R24: HBarghouthi@dctabudhabi.ae | S24: Active
A25: Office of Undersecretary | B25: 4510150 | C25: DCT - Projects Management & Engineering Dept | D25: 4510150 | E25: Executive Office | F25: DCT - Projects Management & Engineering Dept | G25: Hossam Bassem El-Derbi | H25: hderbi@dctabudhabi.ae | I25: Hossam Hamroush | J25: hhamroush@dctabudhabi.ae | K25: Mohamed Elgayar | M25: Mohamed Thabit | N25: mthabet@dctabudhabi.ae | O25: Basel Ahmad AbuYousef | P25: BYousef@dctabudhabi.ae | Q25: Noha Moussa | R25: Noha.Moussa@dctabudhabi.ae | S25: Active
A26: Office of Undersecretary | B26: 4510155 | C26: DCT – Tendering & Projects Control Dept. | D26: 4510155 | E26: Executive Office | F26: DCT – Tendering & Projects Control Dept. | G26: Hossam Bassem El-Derbi | H26: hderbi@dctabudhabi.ae | I26: Hossam Hamroush | J26: hhamroush@dctabudhabi.ae | K26: Mohamed Elgayar | M26: Hiba Hassan | N26: hsleiman@dctabudhabi.ae | O26: Khader Issa Abu Ghannam | P26: KGhannam@dctabudhabi.ae | Q26: Michella Moussi | R26: MMoussi@dctabudhabi.ae | S26: Active
A27: Office of Undersecretary | B27: 4510160 | C27: DCT - Legal & Government Affairs Dept | D27: 4510160 | E27: Executive Office | F27: DCT - Legal & Government Affairs Dept | G27: Hossam Bassem El-Derbi | H27: hderbi@dctabudhabi.ae | I27: Marawan Mostafa Gadalla | J27: mgadalla@dctabudhabi.ae | K27: Mohamed Elgayar | M27: Mohamed Thabit | N27: mthabet@dctabudhabi.ae | O27: Mohammad Ahmed Al Frehat | P27: MFrehat@dctabudhabi.ae | Q27: Halima Kourrate | R27: HKourrate@dctabudhabi.ae | S27: Active
B28: 4510280 | D28: 4510280 | E28: Executive Office | F28: DCT - Al Ain Region Office | G28: Hossam Bassem El-Derbi | H28: hderbi@dctabudhabi.ae | I28: Yasmeen Zuhair Masoud | J28: ymasoud@dctabudhabi.ae | K28: Abdulrahman Alyafei | S28: NOT Active
A29: Office of Undersecretary | B29: 4510011 | C29: DCT - Executive Affairs Department | D29: 4510011 | E29: Executive Office | F29: DCT - Executive Affairs Department | G29: Hossam Bassem El-Derbi | H29: hderbi@dctabudhabi.ae | I29: Yasmeen Zuhair Masoud | J29: ymasoud@dctabudhabi.ae | K29: Abdulrahman Alyafei | M29: Hiba Hassan | N29: hsleiman@dctabudhabi.ae | O29: Saood Abdulaziz Mohamed Al Hosani | P29: SMAlHosani@dctabudhabi.ae | S29: Active
A30: Strategic Affairs | B30: 4512010 | C30: DCT - Strategy Affairs (Central) DEPT. | D30: 4512010 | E30: Strategic Affairs | F30: DCT - Strategy Affairs (Central) DEPT. | G30: Hossam Bassem El-Derbi | H30: hderbi@dctabudhabi.ae | I30: Yasmeen Zuhair Masoud | J30: ymasoud@dctabudhabi.ae | K30: Abdulrahman Alyafei | M30: Shamsa Al Shebli | N30: shamsa.alshebli@dctabudhabi.ae | O30: Saeed Ali Al Fazari | P30: Sfazari@dctabudhabi.ae | Q30: Hanaa AbuShawish | R30: HShawish@dctabudhabi.ae | S30: Active
A31: Strategic Affairs | B31: 4512100 | C31: DCT - Strategy Planning Dept | D31: 4512100 | E31: Strategic Affairs | F31: DCT - Strategy Planning Dept | G31: Hossam Bassem El-Derbi | H31: hderbi@dctabudhabi.ae | I31: Yasmeen Zuhair Masoud | J31: ymasoud@dctabudhabi.ae | K31: Abdulrahman Alyafei | M31: Shamsa Al Shebli | N31: shamsa.alshebli@dctabudhabi.ae | O31: Wail Alkayali Al Alem | P31: wKayali@dctabudhabi.ae | Q31: Hanzada Abdalaziz | R31: HAbdalaziz@dctabudhabi.ae | S31: Active
A32: Strategic Affairs | B32: 4512200 | C32: DCT - Business Intelligence Dept | D32: 4512200 | E32: Strategic Affairs | F32: DCT - Data & AI Department | G32: Hossam Bassem El-Derbi | H32: hderbi@dctabudhabi.ae | I32: Yasmeen Zuhair Masoud | J32: ymasoud@dctabudhabi.ae | K32: Abdulrahman Alyafei | M32: Shamsa Al Shebli | N32: shamsa.alshebli@dctabudhabi.ae | O32: David Millan Ruiz | P32: DMillan@dctabudhabi.ae | Q32: Manish Kumar | R32: MVaidya@dctabudhabi.ae | S32: Active
A33: Strategic Affairs | B33: 4512300 | C33: DCT - Business Continuity Dept | D33: 4512300 | E33: Strategic Affairs | F33: DCT - Business Excellence and Continuity Department | G33: Hossam Bassem El-Derbi | H33: hderbi@dctabudhabi.ae | I33: Yasmeen Zuhair Masoud | J33: ymasoud@dctabudhabi.ae | K33: Abdulrahman Alyafei | M33: Shamsa Al Shebli | N33: shamsa.alshebli@dctabudhabi.ae | O33: Abdulla Nasser Alblooshi | P33: ANBlooshi@dctabudhabi.ae | Q33: Anas Mohd Azeezyeh | R33: AAzeezyeh@dctabudhabi.ae | S33: Active
A34: Strategic Affairs | B34: 4512500 | C34: DCT - Organization Strategy & Transformation Department | D34: 4512500 | E34: Strategic Affairs | F34: DCT - Organization Developments & Change Enablement Department | G34: Hossam Bassem El-Derbi | H34: hderbi@dctabudhabi.ae | I34: Yasmeen Zuhair Masoud | J34: ymasoud@dctabudhabi.ae | K34: Abdulrahman Alyafei | M34: Shamsa Al Shebli | N34: shamsa.alshebli@dctabudhabi.ae | O34: Salma Fouad Fadhel | P34: SAFadhel@dctabudhabi.ae | Q34: Hazim Yousef Abu Al Rous | R34: HZAbuAlRous@dctabudhabi.ae | S34: Active
A35: AD Gaming & Digital | B35: 4518113 | C35: DCT - CMA - Gaming & Digital Development Department | D35: 4518113 | E35: Strategic Affairs | F35: DCT - AD Gaming Business Development Department | G35: Hossam Bassem El-Derbi | H35: hderbi@dctabudhabi.ae | I35: Yasmeen Zuhair Masoud | J35: ymasoud@dctabudhabi.ae | K35: Abdulrahman Alyafei | M35: Mohamed Siyad | N35: mnalakath@dctabudhabi.ae | O35: Hector Frigola Alcalde | P35: HFrigola@dctabudhabi.ae | Q35: Elizabeth Santos Bernardo | R35: EBernardo.ADG@dctabudhabi.ae | S35: Active
D36: 4512600 | E36: Strategic Affairs | F36: DCT - Sandstorm Comics Department | G36: Hossam Bassem El-Derbi | H36: hderbi@dctabudhabi.ae | I36: Yasmeen Zuhair Masoud | J36: ymasoud@dctabudhabi.ae | K36: Abdulrahman Alyafei | M36: Shamsa Al Shebli | N36: shamsa.alshebli@dctabudhabi.ae | O36: Mohammed Hamed Abedin | P36: MAbedin@dctabudhabi.ae | Q36: Julie Cedo | R36: JCedo@dctabudhabi.ae | S36: Active
D37: 4512700 | E37: Strategic Affairs | F37: DCT - Sector Enablement Department | G37: Hossam Bassem El-Derbi | H37: hderbi@dctabudhabi.ae | I37: Yasmeen Zuhair Masoud | J37: ymasoud@dctabudhabi.ae | K37: Abdulrahman Alyafei | S37: NOT Active
A38: Strategic Marketing & Communication | B38: 4513110 | C38: DCT - Creative and Production Department | D38: 4513110 | E38: Strategic Marketing & Communication | F38: DCT - Creative, Social, & Digital Department | G38: Wasim Ali Ali | H38: wali@dctabudhabi.ae | I38: Hossam Hamroush | J38: hhamroush@dctabudhabi.ae | K38: Mohamed Elgayar | M38: Mohamed Siyad | N38: mnalakath@dctabudhabi.ae | O38: Ghadeer Khub | P38: GKhub@dctabudhabi.ae | Q38: Emad Haj Abdul Fattah & Mohammed Abdelwahed | R38: EFattah@dctabudhabi.ae / MAbdelwahed@dctabudhabi.ae | S38: Active
A39: Strategic Marketing & Communication | B39: 4513120 | C39: DCT - Strategic Communications Department | D39: 4513120 | E39: Strategic Marketing & Communication | F39: DCT - Strategic Communications Department | G39: Wasim Ali Ali | H39: wali@dctabudhabi.ae | I39: Hossam Hamroush | J39: hhamroush@dctabudhabi.ae | K39: Mohamed Elgayar | M39: Mohamed Siyad | N39: mnalakath@dctabudhabi.ae | O39: Nishita Virkar | P39: NVirkar@dctabudhabi.ae | Q39: Emad Haj Abdul Fattah & Mohammed Abdelwahed | R39: EFattah@dctabudhabi.ae / MAbdelwahed@dctabudhabi.ae | S39: Active
A40: Strategic Marketing & Communication | B40: 4513130 | C40: DCT - Planning, Strategy & Operations Department | D40: 4513130 | E40: Strategic Marketing & Communication | F40: DCT - Planning, Strategy & Operations Department | G40: Wasim Ali Ali | H40: wali@dctabudhabi.ae | I40: Hossam Hamroush | J40: hhamroush@dctabudhabi.ae | K40: Mohamed Elgayar | M40: Mohamed Siyad | N40: mnalakath@dctabudhabi.ae | O40: Georgios Kalliamvakos | P40: GKalliamvakos@dctabudhabi.ae | Q40: Emad Haj Abdul Fattah & Mohammed Abdelwahed | R40: EFattah@dctabudhabi.ae / MAbdelwahed@dctabudhabi.ae | S40: Active
...

Sheet Director & ED Sep.25
B1: Old Sector | C1: Cost center | D1: Old Department Name-ADERP-as Per DOF | E1: New Cost center | F1: New Sector | G1: New Department Name-ADERP | H1: PBP Emp. Name | I1: Email | J1: FBP Emp Name | K1: Email | L1: FBP -UH | M1: Remarks | N1: Director/ ED Emp Name | O1: Director /ED Email | P1: Key Users Names | Q1: Key Users Email ID | R1: CC status | S1: Action
B2: Abu Dhabi Arabic Language Centre | C2: 4510195 | D2: DCT - Arabic Language Central | E2: 4510195 | F2: Arabic Language Centre | G2: ALC - Arabic Language Centre (Central) | H2: Nader Khaled Sarieddine | I2: nsarieddine@dctabudhabi.ae | J2: Hossam Hamroush | K2: hhamroush@dctabudhabi.ae | L2: Mohamed Elgayar | N2: Saeed H. Al Tunaiji | O2: stanaiji@alc.ae | P2: Iman Saigal, soraya | Q2: SFarag@alc.ae | R2: Active | S2: Name Update
B3: Abu Dhabi Arabic Language Centre | C3: 4519196 | D3: ALC- Marketing & Communications Department | E3: 4519196 | F3: Arabic Language Centre | G3: ALC- Marketing & Communications Department | H3: Nader Khaled Sarieddine | I3: nsarieddine@dctabudhabi.ae | J3: Hossam Hamroush | K3: hhamroush@dctabudhabi.ae | L3: Mohamed Elgayar | N3: Dr.Yasser Mohammed Zamzam | P3: Malek Mohammad Abu Ageel, Hanya Alkhadra, Alicia Avila Al Mutawa, Asma Abdulla Alfalasi | Q3: MAgeel@alc.ae, HAlkhadra@alc.ae, AMutawa@alc.ae, AFalasi@alc.ae | R3: NOT Active | S3: No Action
B4: Abu Dhabi Arabic Language Centre | C4: 4519197 | D4: ALC- Arabic Language Education & Research Department | E4: 4519197 | F4: Arabic Language Centre | G4: ALC- Arabic Language Education & Research Department | H4: Nader Khaled Sarieddine | I4: nsarieddine@dctabudhabi.ae | J4: Hossam Hamroush | K4: hhamroush@dctabudhabi.ae | L4: Mohamed Elgayar | N4: Khalil Alshaikh | P4: Razan Hussein, Mohamed Ghazal | Q4: RaHussein@alc.ae, MGhazal@alc.ae | R4: NOT Active | S4: No Action
B5: Abu Dhabi Arabic Language Centre | C5: 4519199 | D5: ALC- Creative Content Department | E5: 4519199 | F5: Arabic Language Centre | G5: ALC- Creative Content Department | H5: Nader Khaled Sarieddine | I5: nsarieddine@dctabudhabi.ae | J5: Hossam Hamroush | K5: hhamroush@dctabudhabi.ae | L5: Mohamed Elgayar | N5: Nour Diar Bakerli | P5: Muataz Mahmoud Eweidat | Q5: muataz.eweidat@alc.ae | R5: NOT Active | S5: No Action
B6: Abu Dhabi Arabic Language Centre | C6: 4519200 | D6: ALC- Bookfairs & Events Department | E6: 4519200 | F6: Arabic Language Centre | G6: ALC- Bookfairs & Events Department | H6: Nader Khaled Sarieddine | I6: nsarieddine@dctabudhabi.ae | J6: Hossam Hamroush | K6: hhamroush@dctabudhabi.ae | L6: Mohamed Elgayar | N6: Abdulrahman Mohamed Alnaqbi | P6: Irum Fawad Siddiqui, Rahmah Hasan Al-Abidi | Q6: irum.siddiqui@alc.ae, RAbidi@alc.ae | R6: NOT Active | S6: No Action
B7: Abu Dhabi Arabic Language Centre | C7: 4519201 | D7: ALC- Literature Awards Department | E7: 4519201 | F7: Arabic Language Centre | G7: ALC- Literature Awards Department | H7: Nader Khaled Sarieddine | I7: nsarieddine@dctabudhabi.ae | J7: Hossam Hamroush | K7: hhamroush@dctabudhabi.ae | L7: Mohamed Elgayar | N7: Juma Mohammed Ali Al Dhaheri | P7: Sara Mohamed Al Saadi | Q7: SSaadi@alc.ae | R7: NOT Active | S7: No Action
B8: Abu Dhabi Arabic Language Centre | C8: 4519202 | D8: ALC- Specialized Library Department | E8: 4519202 | F8: Arabic Language Centre | G8: ALC- Specialized Library Department | H8: Nader Khaled Sarieddine | I8: nsarieddine@dctabudhabi.ae | J8: Hossam Hamroush | K8: hhamroush@dctabudhabi.ae | L8: Mohamed Elgayar | N8: Karin Aghadjanian | P8: Andrawes Snobar | Q8: ASnobar@alc.ae | R8: NOT Active | S8: No Action
B9: Abu Dhabi Arabic Language Centre | C9: 4519203 | D9: ALC- Strategic Planning Office | E9: 4519203 | F9: Arabic Language Centre | G9: ALC- Strategic Planning Office | H9: Nader Khaled Sarieddine | I9: nsarieddine@dctabudhabi.ae | J9: Hossam Hamroush | K9: hhamroush@dctabudhabi.ae | L9: Mohamed Elgayar | N9: Ayesha Eid AlMazrouei | P9: Ammar Ajlouni | Q9: AAjlouni@alc.ae | R9: NOT Active | S9: No Action
B10: Abu Dhabi Arabic Language Centre | C10: 4519204 | E10: 4519204 | F10: Arabic Language Centre | G10: ALC - Corporate Communication Office Head | H10: Nader Khaled Sarieddine | I10: nsarieddine@dctabudhabi.ae | J10: Hossam Hamroush | K10: hhamroush@dctabudhabi.ae | L10: Mohamed Elgayar
B11: Culture | C11: 4511300 | D11: DCT - Historical Environment Dept | E11: 4511300 | F11: Culture | G11: DCT - Historical Environment Dept | H11: Waddah Mohammad Zanah | I11: wzanah@dctabudhabi.ae | J11: Anwar AL Mussaibi | K11: asalmessabi@dctabudhabi.ae | L11: Mohamed Elgayar | N11: Jaber Saleh Al Merri | O11: Jaber.Almerri@dctabudhabi.ae | P11: Mohammed Abdulla Al Harmoodi | Q11: m.alharmoodi@dctabudhabi.ae | R11: Active | S11: No Action
B12: Culture | C12: 4511600 | D12: DCT - Intangible Heritage Dept | E12: 4511600 | F12: Culture | G12: DCT - Intangible Cultural Heritage Department | H12: Waddah Mohammad Zanah | I12: wzanah@dctabudhabi.ae | J12: Noora Al Bader | K12: nalbadrsharif@dctabudhabi.ae | L12: Mohamed Elgayar | N12: Salama Nasser Al Shamsi/Ahmed Ma'ath Humaid | O12: salshamsi@dctabudhabi.ae/amhumaid@dctabudhabi.ae | P12: Maha Salah Aldeen Kilani | Q12: maha.kilani@dctabudhabi.ae | R12: Active | S12: Name Update
B13: Culture | C13: 4516100 | D13: DCT - Library Dept | E13: 4516100 | F13: Culture | G13: DCT - Library Management Department | H13: Waddah Mohammad Zanah | I13: wzanah@dctabudhabi.ae | J13: Noora Al Bader | K13: nalbadrsharif@dctabudhabi.ae | L13: Mohamed Elgayar | N13: Fatema Abdul Rahman Al Tamimi | O13: fatema.altamimi@dctabudhabi.ae | P13: Jasim Mohamed Al Awadi | Q13: jawadi@dctabudhabi.ae | R13: Active | S13: Name Update
B14: Culture | C14: 4511010 | D14: DCT - Culture (Central) Dept | E14: 4511010 | F14: Culture | G14: DCT - Culture (Central) Dept | H14: Waddah Mohammad Zanah | I14: wzanah@dctabudhabi.ae | J14: Anwar AL Mussaibi | K14: asalmessabi@dctabudhabi.ae | L14: Mohamed Elgayar | N14: Rita Aoun | O14: RAoun@dctabudhabi.ae | P14: Mehdi Rhaiem | Q14: MRhaiem@dctabudhabi.ae | R14: Active | S14: No Action
B15: Culture | C15: 4511011 | D15: DCT - Abu Dhabi Public Art | E15: 4511011 | G15: DCT - Abu Dhabi Public Art | H15: Omer Khan Habib | I15: okhan@dctabudhabi.ae | J15: Anwar AL Mussaibi | K15: asalmessabi@dctabudhabi.ae | L15: Mohamed Elgayar | M15: not required in 2026 | N15: Reem Ghaith Fadda | O15: RFadda@dctabudhabi.ae | P15: Clemence Marie Bergal | Q15: CBergal@dctabudhabi.ae | R15: Active | S15: No Action
B16: Culture | C16: 4511150 | D16: DCT - Culture Planning & Development Dept. | E16: 4511150 | F16: Culture | G16: DCT - Scientific, Curatorial and Collection Department | H16: Waddah Mohammad Zanah | I16: wzanah@dctabudhabi.ae | J16: Anwar AL Mussaibi | K16: asalmessabi@dctabudhabi.ae | L16: Mohamed Elgayar | N16: Mehdi Rhaiem | O16: MRhaiem@dctabudhabi.ae | P16: Mehdi Rhaiem | Q16: MRhaiem@dctabudhabi.ae | R16: Active | S16: Name Update
B17: Culture | C17: 4511250 | D17: DCT - Cultural Sites Dept | E17: 4511250 | F17: Culture | G17: DCT - Culture Sites Management Department | H17: Omer Khan Habib & Waddah Mohammad Zanah | I17: okhan@dctabudhabi.ae wzanah@dctabudhabi.ae | J17: Noora Al Bader | K17: nalbadrsharif@dctabudhabi.ae | L17: Mohamed Elgayar | N17: Salama Nasser Al Shamsi/Ahmed Ma'ath Humaid | O17: salshamsi@dctabudhabi.ae/amhumaid@dctabudhabi.ae | P17: Esraa Mohamed Al Atayeb Yosra El Hassan Imaad Riaz | Q17: EHashim@dctabudhabi.ae YElHassan@dctabudhabi.ae IRiaz@dctabudhabi.ae | R17: Active | S17: Name Update
B18: Culture | C18: 4511550 | D18: DCT - Marketing & Communication Dept. | E18: 4511550 | F18: Culture | G18: DCT - Culture Sector Marketing Department | H18: Omer Khan Habib | I18: okhan@dctabudhabi.ae | J18: Anwar AL Mussaibi | K18: asalmessabi@dctabudhabi.ae | L18: Mohamed Elgayar | N18: Sherine Noural Din AbdelGafar | O18: SAbdelGafar@dctabudhabi.ae | P18: Ehab Hani Haddad | Q18: EHaddad@dctabudhabi.ae | R18: Active | S18: Name Update
B19: Culture | C19: 4511700 | D19: DCT - Cultural Programs Dept | E19: 4511700 | F19: Culture | G19: DCT - Culture Programming Department | H19: Omer Khan Habib | I19: okhan@dctabudhabi.ae | J19: Anwar AL Mussaibi | K19: asalmessabi@dctabudhabi.ae | L19: Mohamed Elgayar | N19: Reem Ghaith Fadda | O19: RFadda@dctabudhabi.ae | P19: Sarah Saadoun | Q19: SSaadoun@dctabudhabi.ae | R19: Active | S19: Name Update
B20: Culture | C20: 4511750 | D20: DCT – Culture Festivals & Platforms Dept | E20: 4511750 | F20: Culture | G20: DCT – Culture Festivals & Platforms Dept | H20: Omer Khan Habib | I20: okhan@dctabudhabi.ae | J20: Noora Al Bader | K20: nalbadrsharif@dctabudhabi.ae | L20: Mohamed Elgayar | N20: Farah Abdulhameed Al Bakoush | O20: FBakoush@dctabudhabi.ae | P20: Jood Mohamed AlJneibi Rowdha Mohamed Alnaqeeb | Q20: JAlJneibi@dctabudhabi.ae RAlnaqeeb@dctabudhabi.ae | R20: Active | S20: No Action
B21: Culture | C21: 4511800 | D21: DCT - Education & Outreach Dept | E21: 4511800 | F21: Culture | G21: DCT - Education & Outreach Dept | H21: Omer Khan Habib | I21: okhan@dctabudhabi.ae | J21: Noora Al Bader | K21: nalbadrsharif@dctabudhabi.ae | L21: Mohamed Elgayar | N21: Ranya Camille Nasser | O21: RNasser@dctabudhabi.ae | P21: Rand Abdul Jabbar Lubna Ali Abdulla Al Teneiji Moza Humaid AlMazroua | Q21: RAbdulJabbar@dctabudhabi.ae LTeneiji@dctabudhabi.ae MAlmazroua@dctabudhabi.ae | R21: Active | S21: No Action
C22: 4511020 | E22: 4511020 | F22: Culture | G22: DCT - Culture Sector Policy and Development Office | J22: Anwar AL Mussaibi | K22: asalmessabi@dctabudhabi.ae | L22: Mohamed Elgayar | R22: NOT Active | S22: Create New Cost Center
B23: Office of Undersecretary | C23: 4510110 | D23: DCT - Executive Mngt Office | E23: 4510110 | F23: Executive Office | G23: DCT - Executive Management Office (Central) | H23: Hossam Bassem El-Derbi | I23: hderbi@dctabudhabi.ae | J23: Amna Hamad Alsuwaidi | K23: amalsuwaidi@dctabudhabi.ae | L23: Mohamed Elgayar | N23: Saood Abdulaziz Mohamed Al Hosani | O23: SMAlHosani@dctabudhabi.ae | P23: Fatima Hamad Al Midfa | Q23: FHMidfa@dctabudhabi.ae | R23: Active | S23: Name Update
B24: Office of Undersecretary | C24: 4510140 | D24: DCT - Internal Audit Dept | E24: 4510140 | F24: Executive Office | G24: DCT - Internal Audit Office | H24: Hossam Bassem El-Derbi | I24: hderbi@dctabudhabi.ae | J24: Amna Hamad Alsuwaidi | K24: amalsuwaidi@dctabudhabi.ae | L24: Mohamed Elgayar | N24: Ashraf Amro | O24: AAmro@dctabudhabi.ae | P24: Hassan Wael Barghouthi | Q24: HBarghouthi@dctabudhabi.ae | R24: Active | S24: Name Update
B25: Office of Undersecretary | C25: 4510150 | D25: DCT - Projects Management & Engineering Dept | E25: 4510150 | F25: Executive Office | G25: DCT - Projects Management & Engineering Dept | H25: Hossam Bassem El-Derbi | I25: hderbi@dctabudhabi.ae | J25: Hossam Hamroush | K25: hhamroush@dctabudhabi.ae | L25: Mohamed Elgayar | N25: Said Ali Al-Khatib | O25: SKhatib@dctabudhabi.ae | P25: Noha Moussa | Q25: Noha.Moussa@dctabudhabi.ae | R25: Active | S25: No Action
B26: Office of Undersecretary | C26: 4510155 | D26: DCT – Tendering & Projects Control Dept. | E26: 4510155 | F26: Executive Office | G26: DCT – Tendering & Projects Control Dept. | H26: Hossam Bassem El-Derbi | I26: hderbi@dctabudhabi.ae | J26: Hossam Hamroush | K26: hhamroush@dctabudhabi.ae | L26: Mohamed Elgayar | N26: Khader Issa Abu Ghannam | O26: KGhannam@dctabudhabi.ae | P26: Michella Moussi | Q26: MMoussi@dctabudhabi.ae | R26: Active | S26: No Action
B27: Office of Undersecretary | C27: 4510160 | D27: DCT - Legal & Government Affairs Dept | E27: 4510160 | F27: Executive Office | G27: DCT - Legal & Government Affairs Dept | H27: Hossam Bassem El-Derbi | I27: hderbi@dctabudhabi.ae | J27: Amna Hamad Alsuwaidi | K27: amalsuwaidi@dctabudhabi.ae | L27: Mohamed Elgayar | N27: Mohammad Ahmed Al Frehat | O27: MFrehat@dctabudhabi.ae | P27: Halima Kourrate | Q27: HKourrate@dctabudhabi.ae | R27: Active | S27: No Action
C28: 4510280 | E28: 4510280 | F28: Executive Office | G28: DCT - Al Ain Region Office | H28: Hossam Bassem El-Derbi | I28: hderbi@dctabudhabi.ae | J28: Yasmeen Zuhair Masoud | K28: ymasoud@dctabudhabi.ae | L28: Mohamed Elgayar | R28: NOT Active | S28: Create New Cost Center
B29: Office of Undersecretary | C29: 4510011 | D29: DCT - Executive Affairs Department | E29: 4510011 | F29: Executive Office | G29: DCT - Executive Affairs Department | H29: Hossam Bassem El-Derbi | I29: hderbi@dctabudhabi.ae | J29: Yasmeen Zuhair Masoud | K29: ymasoud@dctabudhabi.ae | L29: Mohamed Elgayar | R29: NOT Active | S29: No Action
B30: Strategic Affairs | C30: 4512010 | D30: DCT - Strategy Affairs (Central) DEPT. | E30: 4512010 | F30: Strategic Affairs | G30: DCT - Strategy Affairs (Central) DEPT. | H30: Hossam Bassem El-Derbi | I30: hderbi@dctabudhabi.ae | J30: Yasmeen Zuhair Masoud | K30: ymasoud@dctabudhabi.ae | L30: Mohamed Elgayar | N30: Saeed Ali Al Fazari | O30: Sfazari@dctabudhabi.ae | P30: Hanaa AbuShawish | Q30: HShawish@dctabudhabi.ae | R30: Active | S30: No Action
B31: Strategic Affairs | C31: 4512100 | D31: DCT - Strategy Planning Dept | E31: 4512100 | F31: Strategic Affairs | G31: DCT - Strategy Planning Dept | H31: Hossam Bassem El-Derbi | I31: hderbi@dctabudhabi.ae | J31: Yasmeen Zuhair Masoud | K31: ymasoud@dctabudhabi.ae | L31: Mohamed Elgayar | N31: Wail Alkayali Al Alem | O31: wKayali@dctabudhabi.ae | P31: Hanzada Abdalaziz | Q31: HAbdalaziz@dctabudhabi.ae | R31: Active | S31: No Action
B32: Strategic Affairs | C32: 4512200 | D32: DCT - Business Intelligence Dept | E32: 4512200 | F32: Strategic Affairs | G32: DCT - Data & AI Department | H32: Hossam Bassem El-Derbi | I32: hderbi@dctabudhabi.ae | J32: Yasmeen Zuhair Masoud | K32: ymasoud@dctabudhabi.ae | L32: Mohamed Elgayar | N32: David Millan Ruiz | O32: DMillan@dctabudhabi.ae | P32: Manish Kumar | Q32: MVaidya@dctabudhabi.ae | R32: Active | S32: Name Update
B33: Strategic Affairs | C33: 4512300 | D33: DCT - Business Continuity Dept | E33: 4512300 | F33: Strategic Affairs | G33: DCT - Business Excellence and Continuity Department | H33: Hossam Bassem El-Derbi | I33: hderbi@dctabudhabi.ae | J33: Yasmeen Zuhair Masoud | K33: ymasoud@dctabudhabi.ae | L33: Mohamed Elgayar | N33: Abdulla Nasser Alblooshi | O33: ANBlooshi@dctabudhabi.ae | P33: Anas Mohd Azeezyeh | Q33: AAzeezyeh@dctabudhabi.ae | R33: Active | S33: Name Update
B34: Strategic Affairs | C34: 4512500 | D34: DCT - Organization Strategy & Transformation Department | E34: 4512500 | F34: Strategic Affairs | G34: DCT - Organization Developments & Change Enablement Department | H34: Hossam Bassem El-Derbi | I34: hderbi@dctabudhabi.ae | J34: Yasmeen Zuhair Masoud | K34: ymasoud@dctabudhabi.ae | L34: Mohamed Elgayar | R34: NOT Active | S34: Create New Cost Center
B35: AD Gaming & Digital | C35: 4518113 | D35: DCT - CMA - Gaming & Digital Development Department | E35: 4518113 | F35: Strategic Affairs | G35: DCT - AD Gaming Business Development Department | H35: Hossam Bassem El-Derbi | I35: hderbi@dctabudhabi.ae | J35: Yasmeen Zuhair Masoud | K35: ymasoud@dctabudhabi.ae | L35: Mohamed Elgayar | N35: Marcos Muller Habig | O35: MMuller@dctabudhabi.ae | P35: Elizabeth Santos Bernardo | Q35: EBernardo.ADG@dctabudhabi.ae | R35: Active | S35: Name Update
C36: 4512600 | E36: 4512600 | F36: Strategic Affairs | G36: DCT - Sandstorm Comics Department | H36: Hossam Bassem El-Derbi | I36: hderbi@dctabudhabi.ae | J36: Yasmeen Zuhair Masoud | K36: ymasoud@dctabudhabi.ae | L36: Mohamed Elgayar | R36: NOT Active | S36: Create New Cost Center
C37: 4512700 | E37: 4512700 | F37: Strategic Affairs | G37: DCT - Sector Enablement Department | H37: Hossam Bassem El-Derbi | I37: hderbi@dctabudhabi.ae | J37: Yasmeen Zuhair Masoud | K37: ymasoud@dctabudhabi.ae | L37: Mohamed Elgayar | R37: NOT Active | S37: Create New Cost Center
B38: Strategic Marketing & Communication | C38: 4513110 | D38: DCT - Creative and Production Department | E38: 4513110 | F38: Strategic Marketing & Communication | G38: DCT - Creative, Social, & Digital Department | H38: Wasim Ali Ali | I38: wali@dctabudhabi.ae | J38: Said Drissi | K38: sdrissi@dctabudhabi.ae | L38: Mohamed Elgayar | N38: Ghadeer Khub | O38: GKhub@dctabudhabi.ae | P38: Emad Haj Abdul Fattah & Mohammed Abdelwahed | Q38: EFattah@dctabudhabi.ae / MAbdelwahed@dctabudhabi.ae | R38: Active | S38: No Action
B39: Strategic Marketing & Communication | C39: 4513120 | D39: DCT - Strategic Communications Department | E39: 4513120 | F39: Strategic Marketing & Communication | G39: DCT - Strategic Communications Department | H39: Wasim Ali Ali | I39: wali@dctabudhabi.ae | J39: Said Drissi | K39: sdrissi@dctabudhabi.ae | L39: Mohamed Elgayar | N39: Nishita Virkar | O39: NVirkar@dctabudhabi.ae | P39: Emad Haj Abdul Fattah & Mohammed Abdelwahed | Q39: EFattah@dctabudhabi.ae / MAbdelwahed@dctabudhabi.ae | R39: Active | S39: No Action
B40: Strategic Marketing & Communication | C40: 4513130 | D40: DCT - Planning, Strategy & Operations Department | E40: 4513130 | F40: Strategic Marketing & Communication | G40: DCT - Planning, Strategy & Operations Department | H40: Wasim Ali Ali | I40: wali@dctabudhabi.ae | J40: Said Drissi | K40: sdrissi@dctabudhabi.ae | L40: Mohamed Elgayar | N40: Georgios Kalliamvakos | O40: GKalliamvakos@dctabudhabi.ae | P40: Emad Haj Abdul Fattah & Mohammed Abdelwahed | Q40: EFattah@dctabudhabi.ae / MAbdelwahed@dctabudhabi.ae | R40: Active | S40: No Action
...

Sheet Old 
A2: New organization chart details
A5: Required Action | B5: Cost Center | C5: Department Old name | D5: Parent OR Child | E5: Department New name | F5: Comments
A6: Create New Cost Center | B6: New | C6: NA | D6: Child | E6: DCT - Sandstorm Comics Department
A7: Create New Cost Center | B7: New | C7: NA | D7: Child | E7: DCT - Al Ain Region Office Department | F7: Al Ain Region Office is a new office that was approved in March. As per Admin decree
A8: Create New Cost Center | B8: New | C8: NA | D8: Child | E8: DCT - Organization Strategy & Transformation Department | F8: Organization Strategy & Transformation Department is a new department that was approved in March. Admin decree attached.
A9: Create New Cost Center | B9: New | C9: NA | D9: Child | E9: DCT - Sector Enablement Department | F9: There has been a creation of another department, called Sector Enablement Department under SA, which is mainly serving AD Gaming & Comics
A10: Create New Cost Center | B10: New | C10: NA | D10: Child | E10: DCT - Culture Sector Policy and Development | F10: Culture Sector Policy and Development Office was approved in Dec/Jan. Admin decree attached.
A13: Required Action | B13: Cost Center | C13: Department Old name | D13: Parent OR Child | E13: Department New name | F13: Comments
A14: Create New Cost Center | B14: 4518113 | C14: DCT - CMA - Gaming & Digital Development Department | D14: Child | E14: DCT - AD Gaming Business Development Department | F14: Matching | G14: =VLOOKUP(B14,'Director & ED Sep.25'!C:G,4,) -> Strategic Affairs
A15: Amend the Name of Existing Cost Center | B15: 4511300 | C15: DCT - Historical Environment Dept | D15: Child | E15: DCT - Historical Environment Department | F15: Matching | G15: =VLOOKUP(B15,'Director & ED Sep.25'!C:G,4,) -> Culture
A16: Amend the Name of Existing Cost Center | B16: 4511600 | C16: DCT - Intangible Heritage Dept | D16: Child | E16: DCT - Intangible Cultural Heritage Department | G16: =VLOOKUP(B16,'Director & ED Sep.25'!C:G,4,) -> Culture
A17: Amend the Name of Existing Cost Center | B17: 4516100 | C17: DCT - Library Dept | D17: Child | E17: DCT - Library Management Department | G17: =VLOOKUP(B17,'Director & ED Sep.25'!C:G,4,) -> Culture
A18: Amend the Name of Existing Cost Center | B18: 4511010 | C18: DCT - Culture Sector (Central) Dept | D18: Child | E18: DCT - Culture Sector Department | G18: =VLOOKUP(B18,'Director & ED Sep.25'!C:G,4,) -> Culture
A19: Amend the Name of Existing Cost Center | B19: 4511011 | C19: DCT - Abu Dhabi Public Art | D19: Child | E19: NA | F19: Is now under Culture Programming Department | G19: =VLOOKUP(B19,'Director & ED Sep.25'!C:G,4,) -> 0
A20: Amend the Name of Existing Cost Center | B20: 4511150 | C20: DCT - Culture Planning & Development Dept. | D20: Child | E20: DCT - Scientific, Curatorial and Collection Department | F20: Culture Planning Department changed to Scientific, Curatorial and Collection Department in Dec/Jan. As per Admin decree | G20: =VLOOKUP(B20,'Director & ED Sep.25'!C:G,4,) -> Culture
A21: Amend the Name of Existing Cost Center | B21: 4511250 | C21: DCT - Cultural Sites Dept | D21: Child | E21: DCT - Culture Sites Management Department | G21: =VLOOKUP(B21,'Director & ED Sep.25'!C:G,4,) -> Culture
A22: Amend the Name of Existing Cost Center | B22: 4511550 | C22: DCT - Marketing & Communication Dept. | D22: Child | E22: DCT - Culture Sector Marketing Department | F22: Matching | G22: =VLOOKUP(B22,'Director & ED Sep.25'!C:G,4,) -> Culture
A23: Amend the Name of Existing Cost Center | B23: 4511700 | C23: DCT - Cultural Programs Dept | D23: Child | E23: DCT - Culture Programming Department | G23: =VLOOKUP(B23,'Director & ED Sep.25'!C:G,4,) -> Culture
A24: Amend the Name of Existing Cost Center | B24: 4511750 | C24: DCT – Culture Festivals & Platforms Dept | D24: Child | E24: DCT - Culture Festivals & Platforms Department | F24: Matching | G24: =VLOOKUP(B24,'Director & ED Sep.25'!C:G,4,) -> Culture
A25: Amend the Name of Existing Cost Center | B25: 4511800 | C25: DCT - Education & Outreach Dept | D25: Child | E25: DCT - Education & Outreach Department | F25: Matching | G25: =VLOOKUP(B25,'Director & ED Sep.25'!C:G,4,) -> Culture
A26: Amend the Name of Existing Cost Center | B26: 4510110 | C26: DCT - Executive Mngt Office | D26: Child | E26: DCT - Office Of Undersecretary | F26: Neet to confirm | G26: =VLOOKUP(B26,'Director & ED Sep.25'!C:G,4,) -> Executive Office
A27: Amend the Name of Existing Cost Center | B27: 4510140 | C27: DCT - Internal Audit Dept | D27: Child | E27: DCT - Internal Audit Office | G27: =VLOOKUP(B27,'Director & ED Sep.25'!C:G,4,) -> Executive Office
A28: Amend the Name of Existing Cost Center | B28: 4510150 | C28: DCT - Projects Management & Engineering Dept | D28: Child | E28: DCT - Projects Management & Engineering Department | F28: Matching | G28: =VLOOKUP(B28,'Director & ED Sep.25'!C:G,4,) -> Executive Office
A29: Amend the Name of Existing Cost Center | B29: 4510155 | C29: DCT – Tendering & Projects Control Dept. | D29: Child | E29: DCT - Tendering & Projects Control Department | F29: Matching | G29: =VLOOKUP(B29,'Director & ED Sep.25'!C:G,4,) -> Executive Office
A30: Amend the Name of Existing Cost Center | B30: 4510160 | C30: DCT - Legal & Government Affairs Dept | D30: Child | E30: DCT - Legal & Government Affairs Department | F30: Matching | G30: =VLOOKUP(B30,'Director & ED Sep.25'!C:G,4,) -> Executive Office
A31: Amend the Name of Existing Cost Center | B31: 4510011 | C31: DCT - Executive Affairs Department | D31: Child | E31: DCT - Executive Affairs Department | F31: Matching | G31: =VLOOKUP(B31,'Director & ED Sep.25'!C:G,4,) -> Executive Office
A32: Amend the Name of Existing Cost Center | B32: 4512010 | C32: DCT - Strategy Affairs (Central) DEPT. | D32: Child | E32: DCT - Strategic Affairs Sector Executive Director | G32: =VLOOKUP(B32,'Director & ED Sep.25'!C:G,4,) -> Strategic Affairs
A33: Amend the Name of Existing Cost Center | B33: 4512100 | C33: DCT - Strategy Planning Dept | D33: Child | E33: DCT - Strategic Planning Department | G33: =VLOOKUP(B33,'Director & ED Sep.25'!C:G,4,) -> Strategic Affairs
A34: Amend the Name of Existing Cost Center | B34: 4512200 | C34: DCT - Business Intelligence Dept | D34: Child | E34: DCT - Business Intelligence | F34: Business Intelligence Department is recently approved to be retitled as Data & AI Department. As per Admin decree | G34: =VLOOKUP(B34,'Director & ED Sep.25'!C:G,4,) -> Strategic Affairs
A35: Amend the Name of Existing Cost Center | B35: 4512300 | C35: DCT - Business Continuity Dept | D35: Child | E35: DCT - Business Excellence & Continuity Department | G35: =VLOOKUP(B35,'Director & ED Sep.25'!C:G,4,) -> Strategic Affairs
A36: Amend the Name of Existing Cost Center | B36: 4513110 | C36: DCT - Creative and Production Department | D36: Child | E36: DCT - Creative and Production Department | F36: Matching | G36: =VLOOKUP(B36,'Director & ED Sep.25'!C:G,4,) -> Strategic Marketing & Communication
A37: Amend the Name of Existing Cost Center | B37: 4513120 | C37: DCT - Strategic Communications Department | D37: Child | E37: DCT - Strategic Communications Department | F37: Matching | G37: =VLOOKUP(B37,'Director & ED Sep.25'!C:G,4,) -> Strategic Marketing & Communication
A38: Amend the Name of Existing Cost Center | B38: 4513130 | C38: DCT - Planning, Strategy & Operations Department | D38: Child | E38: DCT - Planning, Strategy & Operations Department | F38: Matching | G38: =VLOOKUP(B38,'Director & ED Sep.25'!C:G,4,) -> Strategic Marketing & Communication
A39: Amend the Name of Existing Cost Center | B39: 4513140 | C39: DCT - Sector Marketing Department | D39: Child | E39: DCT - Sector Marketing Department | F39: Matching | G39: =VLOOKUP(B39,'Director & ED Sep.25'!C:G,4,) -> Strategic Marketing & Communication
